Workbook
Name UPDATE: 'Data Sheet'!$E$1

Sheet Profit & Loss
A1: ='Data Sheet'!B1 -> INFOSYS LTD | H1: =UPDATE | M1: SCREENER.IN
A3: Narration | B3: ='Data Sheet'!B16 -> 42460 | C3: ='Data Sheet'!C16 -> 42825 | D3: ='Data Sheet'!D16 -> 43190 | E3: ='Data Sheet'!E16 -> 43555 | F3: ='Data Sheet'!F16 -> 43921 | G3: ='Data Sheet'!G16 -> 44286 | H3: ='Data Sheet'!H16 -> 44651 | I3: ='Data Sheet'!I16 -> 45016 | ... K3: ='Data Sheet'!K16 -> 45747 | L3: Trailing | M3: Best Case | N3: Worst Case
A4: Sales | B4: ='Data Sheet'!B17 -> 62441 | C4: ='Data Sheet'!C17 -> 68484 | D4: ='Data Sheet'!D17 -> 70522 | E4: ='Data Sheet'!E17 -> 82675 | F4: ='Data Sheet'!F17 -> 90791 | G4: ='Data Sheet'!G17 -> 100472 | H4: ='Data Sheet'!H17 -> 121641 | I4: ='Data Sheet'!I17 -> 146767 | ... K4: ='Data Sheet'!K17 -> 162990 | L4: =SUM(Quarters!H4:K4) -> 173173 | M4: =$K4+M23*K4 -> 179688.91 | N4: =$K4+N23*L4 -> 173809.2
A5: Expenses | B5: =SUM('Data Sheet'!B18,'Data Sheet'!B20:B24, -1*'Data Sheet'!B19) -> 45362 | C5: =SUM('Data Sheet'!C18,'Data Sheet'!C20:C24, -1*'Data Sheet'!C19) -> 49880 | D5: =SUM('Data Sheet'!D18,'Data Sheet'!D20:D24, -1*'Data Sheet'!D19) -> 51700 | E5: =SUM('Data Sheet'!E18,'Data Sheet'!E20:E24, -1*'Data Sheet'!E19) -> 62505 | F5: =SUM('Data Sheet'!F18,'Data Sheet'!F20:F24, -1*'Data Sheet'!F19) -> 68524 | G5: =SUM('Data Sheet'!G18,'Data Sheet'!G20:G24, -1*'Data Sheet'!G19) -> 72583 | H5: =SUM('Data Sheet'!H18,'Data Sheet'!H20:H24, -1*'Data Sheet'!H19) -> 90150 | I5: =SUM('Data Sheet'!I18,'Data Sheet'!I20:I24, -1*'Data Sheet'!I19) -> 111637 | ... K5: =SUM('Data Sheet'!K18,'Data Sheet'!K20:K24, -1*'Data Sheet'!K19) -> 123754 | L5: =SUM(Quarters!H5:K5) -> 132187 | M5: =M4-M6 -> 136730.88 | N5: =N4-N6 -> 132672.62
A6: Operating Profit | B6: =B4-B5 -> 17079 | C6: =C4-C5 -> 18604 | D6: =D4-D5 -> 18822 | E6: =E4-E5 -> 20170 | F6: =F4-F5 -> 22267 | G6: =G4-G5 -> 27889 | H6: =H4-H5 -> 31491 | I6: =I4-I5 -> 35130 | ... K6: =K4-K5 -> 39236 | L6: =SUM(Quarters!H6:K6) -> 40986 | M6: =M4*M24 -> 42958.038 | N6: =N4*N24 -> 41136.573
A7: Other Income | B7: ='Data Sheet'!B25 -> 3120 | C7: ='Data Sheet'!C25 -> 3050 | D7: ='Data Sheet'!D25 -> 3311 | E7: ='Data Sheet'!E25 -> 2882 | F7: ='Data Sheet'!F25 -> 2803 | G7: ='Data Sheet'!G25 -> 2201 | H7: ='Data Sheet'!H25 -> 2295 | I7: ='Data Sheet'!I25 -> 2701 | ... K7: ='Data Sheet'!K25 -> 3600 | L7: =SUM(Quarters!H7:K7) -> 3064 | M7: 0 | N7: 0
A8: Depreciation | B8: ='Data Sheet'!B26 -> 1459 | C8: ='Data Sheet'!C26 -> 1703 | D8: ='Data Sheet'!D26 -> 1863 | E8: ='Data Sheet'!E26 -> 2011 | F8: ='Data Sheet'!F26 -> 2893 | G8: ='Data Sheet'!G26 -> 3267 | H8: ='Data Sheet'!H26 -> 3476 | I8: ='Data Sheet'!I26 -> 4225 | ... K8: ='Data Sheet'!K26 -> 4812 | L8: =SUM(Quarters!H8:K8) -> 4776 | M8: =+$L8 -> 4776 | N8: =+$L8 -> 4776
A9: Interest | B9: ='Data Sheet'!B27 -> 0 | C9: ='Data Sheet'!C27 -> 0 | D9: ='Data Sheet'!D27 -> 0 | E9: ='Data Sheet'!E27 -> 0 | F9: ='Data Sheet'!F27 -> 170 | G9: ='Data Sheet'!G27 -> 195 | H9: ='Data Sheet'!H27 -> 200 | I9: ='Data Sheet'!I27 -> 284 | ... K9: ='Data Sheet'!K27 -> 416 | L9: =SUM(Quarters!H9:K9) -> 413 | M9: =+$L9 -> 413 | N9: =+$L9 -> 413
A10: Profit before tax | B10: ='Data Sheet'!B28 -> 18740 | C10: ='Data Sheet'!C28 -> 19951 | D10: ='Data Sheet'!D28 -> 20270 | E10: ='Data Sheet'!E28 -> 21041 | F10: ='Data Sheet'!F28 -> 22007 | G10: ='Data Sheet'!G28 -> 26628 | H10: ='Data Sheet'!H28 -> 30110 | I10: ='Data Sheet'!I28 -> 33322 | ... K10: ='Data Sheet'!K28 -> 37608 | L10: =SUM(Quarters!H10:K10) -> 38861 | M10: =M6+M7-SUM(M8:M9) -> 37769.038 | N10: =N6+N7-SUM(N8:N9) -> 35947.573
A11: Tax | B11: ='Data Sheet'!B29 -> 5251 | C11: ='Data Sheet'!C29 -> 5598 | D11: ='Data Sheet'!D29 -> 4241 | E11: ='Data Sheet'!E29 -> 5631 | F11: ='Data Sheet'!F29 -> 5368 | G11: ='Data Sheet'!G29 -> 7205 | H11: ='Data Sheet'!H29 -> 7964 | I11: ='Data Sheet'!I29 -> 9214 | ... K11: ='Data Sheet'!K29 -> 10858 | L11: =SUM(Quarters!H11:K11) -> 10858 | M11: =IF($L10>0,$L11/$L10,0) -> 0.27940609 | N11: =IF($L10>0,$L11/$L10,0) -> 0.27940609
A12: Net profit | B12: ='Data Sheet'!B30 -> 13489 | C12: ='Data Sheet'!C30 -> 14353 | D12: ='Data Sheet'!D30 -> 16029 | E12: ='Data Sheet'!E30 -> 15404 | F12: ='Data Sheet'!F30 -> 16594 | G12: ='Data Sheet'!G30 -> 19351 | H12: ='Data Sheet'!H30 -> 22110 | I12: ='Data Sheet'!I30 -> 24095 | ... K12: ='Data Sheet'!K30 -> 26713 | L12: =SUM(Quarters!H12:K12) -> 27972 | M12: =M10-M11*M10 -> 27216.139 | N12: =N10-N11*N10 -> 25903.602
A13: EPS | B13: =IF('Data Sheet'!B93>0,B12/'Data Sheet'!B93,0) -> 29.362851 | C13: =IF('Data Sheet'!C93>0,C12/'Data Sheet'!C93,0) -> 31.243606 | D13: =IF('Data Sheet'!D93>0,D12/'Data Sheet'!D93,0) -> 36.694748 | E13: =IF('Data Sheet'!E93>0,E12/'Data Sheet'!E93,0) -> 35.258303 | F13: =IF('Data Sheet'!F93>0,F12/'Data Sheet'!F93,0) -> 38.962198 | G13: =IF('Data Sheet'!G93>0,G12/'Data Sheet'!G93,0) -> 45.41742 | H13: =IF('Data Sheet'!H93>0,H12/'Data Sheet'!H93,0) -> 52.559013 | I13: =IF('Data Sheet'!I93>0,I12/'Data Sheet'!I93,0) -> 58.079834 | ... K13: =IF('Data Sheet'!K93>0,K12/'Data Sheet'!K93,0) -> 64.317531 | L13: =IF('Data Sheet'!$B6>0,'Profit & Loss'!L12/'Data Sheet'!$B6,0) -> 68.974852 | M13: =IF('Data Sheet'!$B6>0,'Profit & Loss'!M12/'Data Sheet'!$B6,0) -> 67.111009 | N13: =IF('Data Sheet'!$B6>0,'Profit & Loss'!N12/'Data Sheet'!$B6,0) -> 63.874486
A14: Price to earning | B14: =IF(B15>0,B15/B13,"") -> 20.745601 | C14: =IF(C15>0,C15/C13,"") -> 16.359507 | D14: =IF(D15>0,D15/D13,"") -> 15.421825 | E14: =IF(E15>0,E15/E13,"") -> 21.097158 | F14: =IF(F15>0,F15/F13,"") -> 16.464677 | G14: =IF(G15>0,G15/G13,"") -> 30.121702 | H14: =IF(H15>0,H15/H13,"") -> 36.280171 | I14: =IF(I15>0,I15/I13,"") -> 24.585986 | ... K14: =IF(K15>0,K15/K13,"") -> 24.420247 | L14: =IF(L13>0,L15/L13,0) -> 18.969232 | M14: =M25 -> 22.919853 | N14: =N25 -> 18.969232
A15: Price | B15: ='Data Sheet'!B90 -> 609.15 | C15: ='Data Sheet'!C90 -> 511.13 | D15: ='Data Sheet'!D90 -> 565.9 | E15: ='Data Sheet'!E90 -> 743.85 | F15: ='Data Sheet'!F90 -> 641.5 | G15: ='Data Sheet'!G90 -> 1368.05 | H15: ='Data Sheet'!H90 -> 1906.85 | I15: ='Data Sheet'!I90 -> 1427.95 | ... K15: ='Data Sheet'!K90 -> 1570.65 | L15: ='Data Sheet'!B8 -> 1308.4 | M15: =M13*M14 -> 1538.1744 | N15: =N13*N14 -> 1211.65
A17: RATIOS:
A18: Dividend Payout | B18: =IF('Data Sheet'!B30>0, 'Data Sheet'!B31/'Data Sheet'!B30, 0) -> 0.41132775 | C18: =IF('Data Sheet'!C30>0, 'Data Sheet'!C31/'Data Sheet'!C30, 0) -> 0.41047865 | D18: =IF('Data Sheet'!D30>0, 'Data Sheet'!D31/'Data Sheet'!D30, 0) -> 0.59052966 | E18: =IF('Data Sheet'!E30>0, 'Data Sheet'!E31/'Data Sheet'!E30, 0) -> 0.59870813 | F18: =IF('Data Sheet'!F30>0, 'Data Sheet'!F31/'Data Sheet'!F30, 0) -> 0.44757141 | G18: =IF('Data Sheet'!G30>0, 'Data Sheet'!G31/'Data Sheet'!G30, 0) -> 0.59271355 | H18: =IF('Data Sheet'!H30>0, 'Data Sheet'!H31/'Data Sheet'!H30, 0) -> 0.58831298 | I18: =IF('Data Sheet'!I30>0, 'Data Sheet'!I31/'Data Sheet'!I30, 0) -> 0.58390537 | ... K18: =IF('Data Sheet'!K30>0, 'Data Sheet'!K31/'Data Sheet'!K30, 0) -> 0.66738292
A19: OPM | B19: =IF(B6>0,B6/B4,0) -> 0.2735222 | C19: =IF(C6>0,C6/C4,0) -> 0.27165469 | D19: =IF(D6>0,D6/D4,0) -> 0.26689544 | E19: =IF(E6>0,E6/E4,0) -> 0.24396734 | F19: =IF(F6>0,F6/F4,0) -> 0.24525559 | G19: =IF(G6>0,G6/G4,0) -> 0.27757982 | H19: =IF(H6>0,H6/H4,0) -> 0.25888475 | I19: =IF(I6>0,I6/I4,0) -> 0.23935898 | ... L19: =IF(L6>0,L6/L4,0) -> 0.23667662
G22: TRENDS: | H22: 10 YEARS | I22: 7 YEARS | J22: 5 YEARS | K22: 3 YEARS | L22: RECENT | M22: BEST | N22: WORST
G23: Sales Growth | H23: =IF(B4=0,"",POWER($K4/B4,1/9)-1) -> 0.11249742 | I23: =IF(D4=0,"",POWER($K4/D4,1/7)-1) -> 0.12713678 | J23: =IF(F4=0,"",POWER($K4/F4,1/5)-1) -> 0.12414836 | K23: =IF(H4=0,"",POWER($K4/H4, 1/3)-1) -> 0.10245362 | L23: =IF(ISERROR(MAX(IF(J4=0,"",(K4-J4)/J4),IF(K4=0,"",(L4-K4)/K4))),"",MAX(IF(J4=0,"",(K4-J4)/J4),IF(K4=0,"",(L4-K4)/K4))) -> 0.062476226 | M23: =MAX(K23:L23) -> 0.10245362 | N23: =MIN(H23:L23) -> 0.062476226
G24: OPM | H24: =IF(SUM(B4:$K$4)=0,"",SUMPRODUCT(B19:$K$19,B4:$K$4)/SUM(B4:$K$4)) -> 0.25188575 | I24: =IF(SUM(E4:$K$4)=0,"",SUMPRODUCT(E19:$K$19,E4:$K$4)/SUM(E4:$K$4)) -> 0.24750467 | J24: =IF(SUM(G4:$K$4)=0,"",SUMPRODUCT(G19:$K$19,G4:$K$4)/SUM(G4:$K$4)) -> 0.24822913 | K24: =IF(SUM(I4:$K$4)=0, "", SUMPRODUCT(I19:$K$19,I4:$K$4)/SUM(I4:$K$4)) -> 0.23906894 | L24: =L19 -> 0.23667662 | M24: =MAX(K24:L24) -> 0.23906894 | N24: =MIN(H24:L24) -> 0.23667662
G25: Price to Earning | H25: =IF(ISERROR(AVERAGEIF(B14:$L14,">0")),"",AVERAGEIF(B14:$L14,">0")) -> 22.560914 | I25: =IF(ISERROR(AVERAGEIF(E14:$L14,">0")),"",AVERAGEIF(E14:$L14,">0")) -> 24.45539 | J25: =IF(ISERROR(AVERAGEIF(G14:$L14,">0")),"",AVERAGEIF(G14:$L14,">0")) -> 26.346881 | K25: =IF(ISERROR(AVERAGEIF(I14:$L14,">0")),"",AVERAGEIF(I14:$L14,">0")) -> 22.919853 | L25: =L14 -> 18.969232 | M25: =MAX(K25:L25) -> 22.919853 | N25: =MIN(H25:L25) -> 18.969232

Sheet Quarters
A1: ='Profit & Loss'!A1 -> INFOSYS LTD | E1: =UPDATE | J1: SCREENER.IN
A3: Narration | B3: ='Data Sheet'!B41 -> 45199 | C3: ='Data Sheet'!C41 -> 45291 | D3: ='Data Sheet'!D41 -> 45382 | E3: ='Data Sheet'!E41 -> 45473 | F3: ='Data Sheet'!F41 -> 45565 | G3: ='Data Sheet'!G41 -> 45657 | H3: ='Data Sheet'!H41 -> 45747 | I3: ='Data Sheet'!I41 -> 45838 | ... K3: ='Data Sheet'!K41 -> 46022
A4: Sales | B4: ='Data Sheet'!B42 -> 38994 | C4: ='Data Sheet'!C42 -> 38821 | D4: ='Data Sheet'!D42 -> 37923 | E4: ='Data Sheet'!E42 -> 39315 | F4: ='Data Sheet'!F42 -> 40986 | G4: ='Data Sheet'!G42 -> 41764 | H4: ='Data Sheet'!H42 -> 40925 | I4: ='Data Sheet'!I42 -> 42279 | ... K4: ='Data Sheet'!K42 -> 45479
A5: Expenses | B5: ='Data Sheet'!B43 -> 29554 | C5: ='Data Sheet'!C43 -> 29684 | D5: ='Data Sheet'!D43 -> 29139 | E5: ='Data Sheet'!E43 -> 29878 | F5: ='Data Sheet'!F43 -> 31177 | G5: ='Data Sheet'!G43 -> 31649 | H5: ='Data Sheet'!H43 -> 31051 | I5: ='Data Sheet'!I43 -> 32336 | ... K5: ='Data Sheet'!K43 -> 34845
A6: Operating Profit | B6: ='Data Sheet'!B50 -> 9440 | C6: ='Data Sheet'!C50 -> 9137 | D6: ='Data Sheet'!D50 -> 8784 | E6: ='Data Sheet'!E50 -> 9437 | F6: ='Data Sheet'!F50 -> 9809 | G6: ='Data Sheet'!G50 -> 10115 | H6: ='Data Sheet'!H50 -> 9874 | I6: ='Data Sheet'!I50 -> 9943 | ... K6: ='Data Sheet'!K50 -> 10634
A7: Other Income | B7: ='Data Sheet'!B44 -> 632 | C7: ='Data Sheet'!C44 -> 789 | D7: ='Data Sheet'!D44 -> 2729 | E7: ='Data Sheet'!E44 -> 838 | F7: ='Data Sheet'!F44 -> 712 | G7: ='Data Sheet'!G44 -> 859 | H7: ='Data Sheet'!H44 -> 1190 | I7: ='Data Sheet'!I44 -> 1042 | ... K7: ='Data Sheet'!K44 -> -150
A8: Depreciation | B8: ='Data Sheet'!B45 -> 1166 | C8: ='Data Sheet'!C45 -> 1176 | D8: ='Data Sheet'!D45 -> 1163 | E8: ='Data Sheet'!E45 -> 1149 | F8: ='Data Sheet'!F45 -> 1160 | G8: ='Data Sheet'!G45 -> 1203 | H8: ='Data Sheet'!H45 -> 1299 | I8: ='Data Sheet'!I45 -> 1140 | ... K8: ='Data Sheet'!K45 -> 1155
A9: Interest | B9: ='Data Sheet'!B46 -> 138 | C9: ='Data Sheet'!C46 -> 131 | D9: ='Data Sheet'!D46 -> 110 | E9: ='Data Sheet'!E46 -> 105 | F9: ='Data Sheet'!F46 -> 108 | G9: ='Data Sheet'!G46 -> 101 | H9: ='Data Sheet'!H46 -> 102 | I9: ='Data Sheet'!I46 -> 105 | ... K9: ='Data Sheet'!K46 -> 100
A10: Profit before tax | B10: ='Data Sheet'!B47 -> 8768 | C10: ='Data Sheet'!C47 -> 8619 | D10: ='Data Sheet'!D47 -> 10240 | E10: ='Data Sheet'!E47 -> 9021 | F10: ='Data Sheet'!F47 -> 9253 | G10: ='Data Sheet'!G47 -> 9670 | H10: ='Data Sheet'!H47 -> 9663 | I10: ='Data Sheet'!I47 -> 9740 | ... K10: ='Data Sheet'!K47 -> 9229
A11: Tax | B11: ='Data Sheet'!B48 -> 2553 | C11: ='Data Sheet'!C48 -> 2506 | D11: ='Data Sheet'!D48 -> 2265 | E11: ='Data Sheet'!E48 -> 2647 | F11: ='Data Sheet'!F48 -> 2737 | G11: ='Data Sheet'!G48 -> 2848 | H11: ='Data Sheet'!H48 -> 2625 | I11: ='Data Sheet'!I48 -> 2816 | ... K11: ='Data Sheet'!K48 -> 2563
A12: Net profit | B12: ='Data Sheet'!B49 -> 6212 | C12: ='Data Sheet'!C49 -> 6106 | D12: ='Data Sheet'!D49 -> 7969 | E12: ='Data Sheet'!E49 -> 6368 | F12: ='Data Sheet'!F49 -> 6506 | G12: ='Data Sheet'!G49 -> 6806 | H12: ='Data Sheet'!H49 -> 7033 | I12: ='Data Sheet'!I49 -> 6921 | ... K12: ='Data Sheet'!K49 -> 6654
A14: OPM | B14: =IF(B4>0,B6/B4,"") -> 0.24208853 | C14: =IF(C4>0,C6/C4,"") -> 0.2353623 | D14: =IF(D4>0,D6/D4,"") -> 0.23162724 | E14: =IF(E4>0,E6/E4,"") -> 0.24003561 | F14: =IF(F4>0,F6/F4,"") -> 0.23932562 | G14: =IF(G4>0,G6/G4,"") -> 0.24219423 | H14: =IF(H4>0,H6/H4,"") -> 0.24127062 | I14: =IF(I4>0,I6/I4,"") -> 0.23517586 | ... K14: =IF(K4>0,K6/K4,"") -> 0.2338222

Sheet Balance Sheet
A1: ='Profit & Loss'!A1 -> INFOSYS LTD | E1: =UPDATE | J1: SCREENER.IN
A3: Narration | B3: ='Data Sheet'!B56 -> 42460 | C3: ='Data Sheet'!C56 -> 42825 | D3: ='Data Sheet'!D56 -> 43190 | E3: ='Data Sheet'!E56 -> 43555 | F3: ='Data Sheet'!F56 -> 43921 | G3: ='Data Sheet'!G56 -> 44286 | H3: ='Data Sheet'!H56 -> 44651 | I3: ='Data Sheet'!I56 -> 45016 | ... K3: ='Data Sheet'!K56 -> 45747
A4: Equity Share Capital | B4: ='Data Sheet'!B57 -> 1144 | C4: ='Data Sheet'!C57 -> 1144 | D4: ='Data Sheet'!D57 -> 1088 | E4: ='Data Sheet'!E57 -> 2170 | F4: ='Data Sheet'!F57 -> 2122 | G4: ='Data Sheet'!G57 -> 2124 | H4: ='Data Sheet'!H57 -> 2098 | I4: ='Data Sheet'!I57 -> 2069 | ... K4: ='Data Sheet'!K57 -> 2073
A5: Reserves | B5: ='Data Sheet'!B58 -> 60600 | C5: ='Data Sheet'!C58 -> 67838 | D5: ='Data Sheet'!D58 -> 63835 | E5: ='Data Sheet'!E58 -> 62778 | F5: ='Data Sheet'!F58 -> 63328 | G5: ='Data Sheet'!G58 -> 74227 | H5: ='Data Sheet'!H58 -> 73252 | I5: ='Data Sheet'!I58 -> 73338 | ... K5: ='Data Sheet'!K58 -> 93745
A6: Borrowings | B6: ='Data Sheet'!B59 -> 0 | C6: ='Data Sheet'!C59 -> 0 | D6: ='Data Sheet'!D59 -> 0 | E6: ='Data Sheet'!E59 -> 0 | F6: ='Data Sheet'!F59 -> 4633 | G6: ='Data Sheet'!G59 -> 5325 | H6: ='Data Sheet'!H59 -> 5474 | I6: ='Data Sheet'!I59 -> 8299 | ... K6: ='Data Sheet'!K59 -> 8227
A7: Other Liabilities | B7: ='Data Sheet'!B60 -> 13354 | C7: ='Data Sheet'!C60 -> 14166 | D7: ='Data Sheet'!D60 -> 14426 | E7: ='Data Sheet'!E60 -> 19118 | F7: ='Data Sheet'!F60 -> 21717 | G7: ='Data Sheet'!G60 -> 25835 | H7: ='Data Sheet'!H60 -> 35905 | I7: ='Data Sheet'!I60 -> 40890 | ... K7: ='Data Sheet'!K60 -> 43750
A8: Total | B8: ='Data Sheet'!B61 -> 75098 | C8: ='Data Sheet'!C61 -> 83148 | D8: ='Data Sheet'!D61 -> 79349 | E8: ='Data Sheet'!E61 -> 84066 | F8: ='Data Sheet'!F61 -> 91800 | G8: ='Data Sheet'!G61 -> 107511 | H8: ='Data Sheet'!H61 -> 116729 | I8: ='Data Sheet'!I61 -> 124596 | ... K8: ='Data Sheet'!K61 -> 147795
A10: Net Block | B10: ='Data Sheet'!B62 -> 13386 | C10: ='Data Sheet'!C62 -> 14179 | D10: ='Data Sheet'!D62 -> 12574 | E10: ='Data Sheet'!E62 -> 15710 | F10: ='Data Sheet'!F62 -> 23789 | G10: ='Data Sheet'!G62 -> 25505 | H10: ='Data Sheet'!H62 -> 25800 | I10: ='Data Sheet'!I62 -> 29225 | ... K10: ='Data Sheet'!K62 -> 30961
A11: Capital Work in Progress | B11: ='Data Sheet'!B63 -> 960 | C11: ='Data Sheet'!C63 -> 1365 | D11: ='Data Sheet'!D63 -> 1606 | E11: ='Data Sheet'!E63 -> 1388 | F11: ='Data Sheet'!F63 -> 954 | G11: ='Data Sheet'!G63 -> 922 | H11: ='Data Sheet'!H63 -> 416 | I11: ='Data Sheet'!I63 -> 288 | ... K11: ='Data Sheet'!K63 -> 814
A12: Investments | B12: ='Data Sheet'!B64 -> 1892 | C12: ='Data Sheet'!C64 -> 16423 | D12: ='Data Sheet'!D64 -> 12163 | E12: ='Data Sheet'!E64 -> 11261 | F12: ='Data Sheet'!F64 -> 8792 | G12: ='Data Sheet'!G64 -> 14205 | H12: ='Data Sheet'!H64 -> 20324 | I12: ='Data Sheet'!I64 -> 19478 | ... K12: ='Data Sheet'!K64 -> 23541
A13: Other Assets | B13: ='Data Sheet'!B65 -> 58860 | C13: ='Data Sheet'!C65 -> 51181 | D13: ='Data Sheet'!D65 -> 53006 | E13: ='Data Sheet'!E65 -> 55707 | F13: ='Data Sheet'!F65 -> 58265 | G13: ='Data Sheet'!G65 -> 66879 | H13: ='Data Sheet'!H65 -> 70189 | I13: ='Data Sheet'!I65 -> 75605 | ... K13: ='Data Sheet'!K65 -> 92479
A14: Total | B14: ='Data Sheet'!B66 -> 75098 | C14: ='Data Sheet'!C66 -> 83148 | D14: ='Data Sheet'!D66 -> 79349 | E14: ='Data Sheet'!E66 -> 84066 | F14: ='Data Sheet'!F66 -> 91800 | G14: ='Data Sheet'!G66 -> 107511 | H14: ='Data Sheet'!H66 -> 116729 | I14: ='Data Sheet'!I66 -> 124596 | ... K14: ='Data Sheet'!K66 -> 147795
A16: Working Capital | B16: =B13-B7 -> 45506 | C16: =C13-C7 -> 37015 | D16: =D13-D7 -> 38580 | E16: =E13-E7 -> 36589 | F16: =F13-F7 -> 36548 | G16: =G13-G7 -> 41044 | H16: =H13-H7 -> 34284 | I16: =I13-I7 -> 34715 | ... K16: =K13-K7 -> 48729
A17: Debtors | B17: ='Data Sheet'!B67 -> 11330 | C17: ='Data Sheet'!C67 -> 12322 | D17: ='Data Sheet'!D67 -> 13142 | E17: ='Data Sheet'!E67 -> 14827 | F17: ='Data Sheet'!F67 -> 18487 | G17: ='Data Sheet'!G67 -> 19294 | H17: ='Data Sheet'!H67 -> 22698 | I17: ='Data Sheet'!I67 -> 25424 | ... K17: ='Data Sheet'!K67 -> 31158
A18: Inventory | B18: ='Data Sheet'!B68 -> 0 | C18: ='Data Sheet'!C68 -> 0 | D18: ='Data Sheet'!D68 -> 0 | E18: ='Data Sheet'!E68 -> 0 | F18: ='Data Sheet'!F68 -> 0 | G18: ='Data Sheet'!G68 -> 0 | H18: ='Data Sheet'!H68 -> 0 | I18: ='Data Sheet'!I68 -> 0 | ... K18: ='Data Sheet'!K68 -> 0
A20: Debtor Days | B20: =IF('Profit & Loss'!B4>0,'Balance Sheet'!B17/('Profit & Loss'!B4/365),0) -> 66.229721 | C20: =IF('Profit & Loss'!C4>0,'Balance Sheet'!C17/('Profit & Loss'!C4/365),0) -> 65.672712 | D20: =IF('Profit & Loss'!D4>0,'Balance Sheet'!D17/('Profit & Loss'!D4/365),0) -> 68.018916 | E20: =IF('Profit & Loss'!E4>0,'Balance Sheet'!E17/('Profit & Loss'!E4/365),0) -> 65.459389 | F20: =IF('Profit & Loss'!F4>0,'Balance Sheet'!F17/('Profit & Loss'!F4/365),0) -> 74.321849 | G20: =IF('Profit & Loss'!G4>0,'Balance Sheet'!G17/('Profit & Loss'!G4/365),0) -> 70.092265 | H20: =IF('Profit & Loss'!H4>0,'Balance Sheet'!H17/('Profit & Loss'!H4/365),0) -> 68.108368 | I20: =IF('Profit & Loss'!I4>0,'Balance Sheet'!I17/('Profit & Loss'!I4/365),0) -> 63.227837 | ... K20: =IF('Profit & Loss'!K4>0,'Balance Sheet'!K17/('Profit & Loss'!K4/365),0) -> 69.775262
A21: Inventory Turnover | B21: =IF('Balance Sheet'!B18>0,'Profit & Loss'!B4/'Balance Sheet'!B18,0) -> 0 | C21: =IF('Balance Sheet'!C18>0,'Profit & Loss'!C4/'Balance Sheet'!C18,0) -> 0 | D21: =IF('Balance Sheet'!D18>0,'Profit & Loss'!D4/'Balance Sheet'!D18,0) -> 0 | E21: =IF('Balance Sheet'!E18>0,'Profit & Loss'!E4/'Balance Sheet'!E18,0) -> 0 | F21: =IF('Balance Sheet'!F18>0,'Profit & Loss'!F4/'Balance Sheet'!F18,0) -> 0 | G21: =IF('Balance Sheet'!G18>0,'Profit & Loss'!G4/'Balance Sheet'!G18,0) -> 0 | H21: =IF('Balance Sheet'!H18>0,'Profit & Loss'!H4/'Balance Sheet'!H18,0) -> 0 | I21: =IF('Balance Sheet'!I18>0,'Profit & Loss'!I4/'Balance Sheet'!I18,0) -> 0 | ... K21: =IF('Balance Sheet'!K18>0,'Profit & Loss'!K4/'Balance Sheet'!K18,0) -> 0
A23: Return on Equity | B23: =IF(SUM('Balance Sheet'!B4:B5)>0,'Profit & Loss'!B12/SUM('Balance Sheet'!B4:B5),"") -> 0.21846657 | C23: =IF(SUM('Balance Sheet'!C4:C5)>0,'Profit & Loss'!C12/SUM('Balance Sheet'!C4:C5),"") -> 0.20806877 | D23: =IF(SUM('Balance Sheet'!D4:D5)>0,'Profit & Loss'!D12/SUM('Balance Sheet'!D4:D5),"") -> 0.24689247 | E23: =IF(SUM('Balance Sheet'!E4:E5)>0,'Profit & Loss'!E12/SUM('Balance Sheet'!E4:E5),"") -> 0.23717435 | F23: =IF(SUM('Balance Sheet'!F4:F5)>0,'Profit & Loss'!F12/SUM('Balance Sheet'!F4:F5),"") -> 0.25353705 | G23: =IF(SUM('Balance Sheet'!G4:G5)>0,'Profit & Loss'!G12/SUM('Balance Sheet'!G4:G5),"") -> 0.25344789 | H23: =IF(SUM('Balance Sheet'!H4:H5)>0,'Profit & Loss'!H12/SUM('Balance Sheet'!H4:H5),"") -> 0.29343066 | I23: =IF(SUM('Balance Sheet'!I4:I5)>0,'Profit & Loss'!I12/SUM('Balance Sheet'!I4:I5),"") -> 0.31953267 | ... K23: =IF(SUM('Balance Sheet'!K4:K5)>0,'Profit & Loss'!K12/SUM('Balance Sheet'!K4:K5),"") -> 0.27878895
A24: Return on Capital Emp | C24: =IF((B4+B5+B6+C4+C5+C6)>0,('Profit & Loss'!C10+'Profit & Loss'!C9)*2/(B4+B5+B6+C4+C5+C6),"") -> 0.30523385 | D24: =IF((C4+C5+C6+D4+D5+D6)>0,('Profit & Loss'!D10+'Profit & Loss'!D9)*2/(C4+C5+C6+D4+D5+D6),"") -> 0.30275195 | E24: =IF((D4+D5+D6+E4+E5+E6)>0,('Profit & Loss'!E10+'Profit & Loss'!E9)*2/(D4+D5+D6+E4+E5+E6),"") -> 0.32402923 | F24: =IF((E4+E5+E6+F4+F5+F6)>0,('Profit & Loss'!F10+'Profit & Loss'!F9)*2/(E4+E5+E6+F4+F5+F6),"") -> 0.32847272 | G24: =IF((F4+F5+F6+G4+G5+G6)>0,('Profit & Loss'!G10+'Profit & Loss'!G9)*2/(F4+F5+F6+G4+G5+G6),"") -> 0.35349469 | H24: =IF((G4+G5+G6+H4+H5+H6)>0,('Profit & Loss'!H10+'Profit & Loss'!H9)*2/(G4+G5+G6+H4+H5+H6),"") -> 0.37304615 | I24: =IF((H4+H5+H6+I4+I5+I6)>0,('Profit & Loss'!I10+'Profit & Loss'!I9)*2/(H4+H5+H6+I4+I5+I6),"") -> 0.40850909 | J24: =IF((I4+I5+I6+J4+J5+J6)>0,('Profit & Loss'!J10+'Profit & Loss'!J9)*2/(I4+I5+I6+J4+J5+J6),"") -> 0.40468196 | K24: =IF((J4+J5+J6+K4+K5+K6)>0,('Profit & Loss'!K10+'Profit & Loss'!K9)*2/(J4+J5+J6+K4+K5+K6),"") -> 0.37925394

Sheet Cash Flow
A1: ='Balance Sheet'!A1 -> INFOSYS LTD | E1: =UPDATE | J1: SCREENER.IN
A3: Narration | B3: ='Data Sheet'!B81 -> 42460 | C3: ='Data Sheet'!C81 -> 42825 | D3: ='Data Sheet'!D81 -> 43190 | E3: ='Data Sheet'!E81 -> 43555 | F3: ='Data Sheet'!F81 -> 43921 | G3: ='Data Sheet'!G81 -> 44286 | H3: ='Data Sheet'!H81 -> 44651 | I3: ='Data Sheet'!I81 -> 45016 | ... K3: ='Data Sheet'!K81 -> 45747
A4: Cash from Operating Activity | B4: ='Data Sheet'!B82 -> 10028 | C4: ='Data Sheet'!C82 -> 11531 | D4: ='Data Sheet'!D82 -> 13218 | E4: ='Data Sheet'!E82 -> 14841 | F4: ='Data Sheet'!F82 -> 17003 | G4: ='Data Sheet'!G82 -> 23224 | H4: ='Data Sheet'!H82 -> 23885 | I4: ='Data Sheet'!I82 -> 22467 | ... K4: ='Data Sheet'!K82 -> 35694
A5: Cash from Investing Activity | B5: ='Data Sheet'!B83 -> -885 | C5: ='Data Sheet'!C83 -> -14664 | D5: ='Data Sheet'!D83 -> 4533 | E5: ='Data Sheet'!E83 -> -632 | F5: ='Data Sheet'!F83 -> -331 | G5: ='Data Sheet'!G83 -> -7373 | H5: ='Data Sheet'!H83 -> -6485 | I5: ='Data Sheet'!I83 -> -1071 | ... K5: ='Data Sheet'!K83 -> -1864
A6: Cash from Financing Activity | B6: ='Data Sheet'!B84 -> -6813 | C6: ='Data Sheet'!C84 -> -6939 | D6: ='Data Sheet'!D84 -> -20505 | E6: ='Data Sheet'!E84 -> -14512 | F6: ='Data Sheet'!F84 -> -17591 | G6: ='Data Sheet'!G84 -> -9786 | H6: ='Data Sheet'!H84 -> -24642 | I6: ='Data Sheet'!I84 -> -26695 | ... K6: ='Data Sheet'!K84 -> -24161
A7: Net Cash Flow | B7: ='Data Sheet'!B85 -> 2330 | C7: ='Data Sheet'!C85 -> -10072 | D7: ='Data Sheet'!D85 -> -2754 | E7: ='Data Sheet'!E85 -> -303 | F7: ='Data Sheet'!F85 -> -919 | G7: ='Data Sheet'!G85 -> 6065 | H7: ='Data Sheet'!H85 -> -7242 | I7: ='Data Sheet'!I85 -> -5299 | ... K7: ='Data Sheet'!K85 -> 9669

Sheet Financials>

Sheet Historical FS
B2: ="Historical Financial Statement - "&'Data Sheet'!B1 -> Historical Financial Statement - INFOSYS LTD
B3: Years | C3: ='Data Sheet'!B16 -> 42460 | D3: ='Data Sheet'!C16 -> 42825 | E3: ='Data Sheet'!D16 -> 43190 | F3: ='Data Sheet'!E16 -> 43555 | G3: ='Data Sheet'!F16 -> 43921 | H3: ='Data Sheet'!G16 -> 44286 | I3: ='Data Sheet'!H16 -> 44651 | J3: ='Data Sheet'!I16 -> 45016 | ... L3: ='Data Sheet'!K16 -> 45747 | M3: LTM
A5: # | B5: Income Statement
B6: Sales | C6: =IFERROR('Data Sheet'!B17,'Data Sheet'!C17) -> 62441 | D6: =IFERROR('Data Sheet'!C17,'Data Sheet'!D17) -> 68484 | E6: =IFERROR('Data Sheet'!D17,'Data Sheet'!E17) -> 70522 | F6: =IFERROR('Data Sheet'!E17,'Data Sheet'!F17) -> 82675 | G6: =IFERROR('Data Sheet'!F17,'Data Sheet'!G17) -> 90791 | H6: =IFERROR('Data Sheet'!G17,'Data Sheet'!H17) -> 100472 | I6: =IFERROR('Data Sheet'!H17,'Data Sheet'!I17) -> 121641 | J6: =IFERROR('Data Sheet'!I17,'Data Sheet'!J17) -> 146767 | ... L6: =IFERROR('Data Sheet'!K17,'Data Sheet'!L17) -> 162990 | M6: =IFERROR(SUM('Data Sheet'!H42:K42),0) -> 173173
B7: Sales Growth | D7: =D6/C6-1 -> 0.09677936 | E7: =E6/D6-1 -> 0.029758776 | F7: =F6/E6-1 -> 0.1723292 | G7: =G6/F6-1 -> 0.098167523 | H7: =H6/G6-1 -> 0.10662951 | I7: =I6/H6-1 -> 0.21069552 | J7: =J6/I6-1 -> 0.20655864 | K7: =K6/J6-1 -> 0.047033734 | ... M7: =M6/L6-1 -> 0.062476226
B9: COGS | C9: =IFERROR(SUM('Data Sheet'!B20:B22)-1*'Data Sheet'!B19,0) -> 40492 | D9: =IFERROR(SUM('Data Sheet'!C20:C22)-1*'Data Sheet'!C19,0) -> 44609 | E9: =IFERROR(SUM('Data Sheet'!D20:D22)-1*'Data Sheet'!D19,0) -> 46395 | F9: =IFERROR(SUM('Data Sheet'!E20:E22)-1*'Data Sheet'!E19,0) -> 55446 | G9: =IFERROR(SUM('Data Sheet'!F20:F22)-1*'Data Sheet'!F19,0) -> 62210 | H9: =IFERROR(SUM('Data Sheet'!G20:G22)-1*'Data Sheet'!G19,0) -> 68490 | I9: =IFERROR(SUM('Data Sheet'!H20:H22)-1*'Data Sheet'!H19,0) -> 84819 | J9: =IFERROR(SUM('Data Sheet'!I20:I22)-1*'Data Sheet'!I19,0) -> 104880 | ... L9: =IFERROR(SUM('Data Sheet'!K20:K22)-1*'Data Sheet'!K19,0) -> 116585 | M9: =IFERROR(SUM('Data Sheet'!H43:K43),0) -> 132187
B10: COGS % sales | C10: =C9/C6 -> 0.64848417 | D10: =D9/D6 -> 0.65137842 | E10: =E9/E6 -> 0.65787981 | F10: =F9/F6 -> 0.67065014 | G10: =G9/G6 -> 0.68520007 | H10: =H9/H6 -> 0.68168246 | I10: =I9/I6 -> 0.69728957 | J10: =J9/J6 -> 0.71460206 | ... M10: =M9/M6 -> 0.76332338
B12: Gross Profit | C12: =C6-C9 -> 21949 | D12: =D6-D9 -> 23875 | E12: =E6-E9 -> 24127 | F12: =F6-F9 -> 27229 | G12: =G6-G9 -> 28581 | H12: =H6-H9 -> 31982 | I12: =I6-I9 -> 36822 | J12: =J6-J9 -> 41887 | ... M12: =M6-M9 -> 40986
B13: Gross Margin | C13: =C12/C6 -> 0.35151583 | D13: =D12/D6 -> 0.34862158 | E13: =E12/E6 -> 0.34212019 | F13: =F12/F6 -> 0.32934986 | G13: =G12/G6 -> 0.31479993 | H13: =H12/H6 -> 0.31831754 | I13: =I12/I6 -> 0.30271043 | J13: =J12/J6 -> 0.28539794 | ... M13: =M12/M6 -> 0.23667662
B15: Selling & Admin Exp. | C15: =IFERROR(SUM('Data Sheet'!B23:B24),0) -> 4870 | D15: =IFERROR(SUM('Data Sheet'!C23:C24),0) -> 5271 | E15: =IFERROR(SUM('Data Sheet'!D23:D24),0) -> 5305 | F15: =IFERROR(SUM('Data Sheet'!E23:E24),0) -> 7059 | G15: =IFERROR(SUM('Data Sheet'!F23:F24),0) -> 6314 | H15: =IFERROR(SUM('Data Sheet'!G23:G24),0) -> 4093 | I15: =IFERROR(SUM('Data Sheet'!H23:H24),0) -> 5331 | J15: =IFERROR(SUM('Data Sheet'!I23:I24),0) -> 6757 | ... L15: =IFERROR(SUM('Data Sheet'!K23:K24),0) -> 7169
B16: S & A % Sales | C16: =C15/C6 -> 0.077993626 | D16: =D15/D6 -> 0.076966883 | E16: =E15/E6 -> 0.075224753 | F16: =F15/F6 -> 0.085382522 | G16: =G15/G6 -> 0.069544338 | H16: =H15/H6 -> 0.040737718 | I16: =I15/I6 -> 0.043825684 | J16: =J15/J6 -> 0.04603896 | ... L16: =L15/L6 -> 0.043984294
B18: EBITDA | C18: =C12-C15 -> 17079 | D18: =D12-D15 -> 18604 | E18: =E12-E15 -> 18822 | F18: =F12-F15 -> 20170 | G18: =G12-G15 -> 22267 | H18: =H12-H15 -> 27889 | I18: =I12-I15 -> 31491 | J18: =J12-J15 -> 35130 | ... M18: =M12-M15 -> 40986
B19: EBITDA % Sales | C19: =C18/C6 -> 0.2735222 | D19: =D18/D6 -> 0.27165469 | E19: =E18/E6 -> 0.26689544 | F19: =F18/F6 -> 0.24396734 | G19: =G18/G6 -> 0.24525559 | H19: =H18/H6 -> 0.27757982 | I19: =I18/I6 -> 0.25888475 | J19: =J18/J6 -> 0.23935898 | ... M19: =M18/M6 -> 0.23667662
B21: Interest | C21: =IFERROR(SUM('Data Sheet'!B27),0) -> 0 | D21: =IFERROR(SUM('Data Sheet'!C27),0) -> 0 | E21: =IFERROR(SUM('Data Sheet'!D27),0) -> 0 | F21: =IFERROR(SUM('Data Sheet'!E27),0) -> 0 | G21: =IFERROR(SUM('Data Sheet'!F27),0) -> 170 | H21: =IFERROR(SUM('Data Sheet'!G27),0) -> 195 | I21: =IFERROR(SUM('Data Sheet'!H27),0) -> 200 | J21: =IFERROR(SUM('Data Sheet'!I27),0) -> 284 | ... L21: =IFERROR(SUM('Data Sheet'!K27),0) -> 416 | M21: =IFERROR(SUM('Data Sheet'!H46:K46),) -> 413
B22: Interest % Sales | C22: =C21/C6 -> 0 | D22: =D21/D6 -> 0 | E22: =E21/E6 -> 0 | F22: =F21/F6 -> 0 | G22: =G21/G6 -> 0.0018724323 | H22: =H21/H6 -> 0.0019408392 | I22: =I21/I6 -> 0.0016441825 | J22: =J21/J6 -> 0.0019350399 | ... M22: =M21/M6 -> 0.0023848983
B24: Depreciation | C24: =IFERROR(SUM('Data Sheet'!B26),0) -> 1459 | D24: =IFERROR(SUM('Data Sheet'!C26),0) -> 1703 | E24: =IFERROR(SUM('Data Sheet'!D26),0) -> 1863 | F24: =IFERROR(SUM('Data Sheet'!E26),0) -> 2011 | G24: =IFERROR(SUM('Data Sheet'!F26),0) -> 2893 | H24: =IFERROR(SUM('Data Sheet'!G26),0) -> 3267 | I24: =IFERROR(SUM('Data Sheet'!H26),0) -> 3476 | J24: =IFERROR(SUM('Data Sheet'!I26),0) -> 4225 | ... L24: =IFERROR(SUM('Data Sheet'!K26),0) -> 4812 | M24: =IFERROR(SUM('Data Sheet'!H45:K45),0) -> 4776
B25: Depreciation % Sales | C25: =C24/C6 -> 0.023366058 | D25: =D24/D6 -> 0.024867122 | E25: =E24/E6 -> 0.026417288 | F25: =F24/F6 -> 0.024324161 | G25: =G24/G6 -> 0.031864392 | H25: =H24/H6 -> 0.032516522 | I25: =I24/I6 -> 0.028575891 | J25: =J24/J6 -> 0.028787125 | ... M25: =M24/M6 -> 0.027579357
B27: Earning Before Tax | C27: =IFERROR(C18-SUM(C24,C21),0) -> 15620 | D27: =IFERROR(D18-SUM(D24,D21),0) -> 16901 | E27: =IFERROR(E18-SUM(E24,E21),0) -> 16959 | F27: =IFERROR(F18-SUM(F24,F21),0) -> 18159 | G27: =IFERROR(G18-SUM(G24,G21),0) -> 19204 | H27: =IFERROR(H18-SUM(H24,H21),0) -> 24427 | I27: =IFERROR(I18-SUM(I24,I21),0) -> 27815 | J27: =IFERROR(J18-SUM(J24,J21),0) -> 30621 | ... L27: =IFERROR(L18-SUM(L24,L21),0) -> 34008 | M27: =IFERROR(SUM('Data Sheet'!H47:K47),0) -> 38861
B28: EBT % Sales | C28: =C27/C6 -> 0.25015615 | D28: =D27/D6 -> 0.24678757 | E28: =E27/E6 -> 0.24047815 | F28: =F27/F6 -> 0.21964318 | G28: =G27/G6 -> 0.21151876 | H28: =H27/H6 -> 0.24312246 | I28: =I27/I6 -> 0.22866468 | J28: =J27/J6 -> 0.20863682 | ... M28: =M27/M6 -> 0.22440565
B30: Tax | C30: =IFERROR(SUM('Data Sheet'!B29),0) -> 5251 | D30: =IFERROR(SUM('Data Sheet'!C29),0) -> 5598 | E30: =IFERROR(SUM('Data Sheet'!D29),0) -> 4241 | F30: =IFERROR(SUM('Data Sheet'!E29),0) -> 5631 | G30: =IFERROR(SUM('Data Sheet'!F29),0) -> 5368 | H30: =IFERROR(SUM('Data Sheet'!G29),0) -> 7205 | I30: =IFERROR(SUM('Data Sheet'!H29),0) -> 7964 | J30: =IFERROR(SUM('Data Sheet'!I29),0) -> 9214 | ... L30: =IFERROR(SUM('Data Sheet'!K29),0) -> 10858 | M30: =IFERROR(SUM('Data Sheet'!H48:K48),0) -> 10858
B31: Effective Tax Rate | C31: =C30/C27 -> 0.33617157 | D31: =D30/D27 -> 0.331223 | E31: =E30/E27 -> 0.25007371 | F31: =F30/F27 -> 0.31009417 | G31: =G30/G27 -> 0.2795251 | H31: =H30/H27 -> 0.29496049 | I31: =I30/I27 -> 0.28632033 | J31: =J30/J27 -> 0.30090461 | ... M31: =M30/M27 -> 0.27940609
B33: Net Profit | C33: =(C27-C30) -> 10369 | D33: =(D27-D30) -> 11303 | E33: =(E27-E30) -> 12718 | F33: =(F27-F30) -> 12528 | G33: =(G27-G30) -> 13836 | H33: =(H27-H30) -> 17222 | I33: =(I27-I30) -> 19851 | J33: =(J27-J30) -> 21407 | ... M33: =(M27-M30) -> 28003
B34: Net Margin | C34: =C33/C6 -> 0.16606076 | D34: =D33/D6 -> 0.16504585 | E34: =E33/E6 -> 0.18034089 | F34: =F33/F6 -> 0.15153311 | G34: =G33/G6 -> 0.15239396 | H34: =H33/H6 -> 0.17141094 | I34: =I33/I6 -> 0.16319333 | J34: =J33/J6 -> 0.14585704 | ... M34: =M33/M6 -> 0.16170535
B36: No. of Shares | C36: =IFERROR('Data Sheet'!B93,0) -> 459.39 | D36: =IFERROR('Data Sheet'!C93,0) -> 459.39 | E36: =IFERROR('Data Sheet'!D93,0) -> 436.82 | F36: =IFERROR('Data Sheet'!E93,0) -> 436.89 | G36: =IFERROR('Data Sheet'!F93,0) -> 425.9 | H36: =IFERROR('Data Sheet'!G93,0) -> 426.07 | I36: =IFERROR('Data Sheet'!H93,0) -> 420.67 | J36: =IFERROR('Data Sheet'!I93,0) -> 414.86 | ... M36: =IFERROR('Data Sheet'!L93,0) -> 0
B38: Earning Per Shares | C38: =C33/C36 -> 22.571236 | D38: =D33/D36 -> 24.604367 | E38: =E33/E36 -> 29.114967 | F38: =F33/F36 -> 28.67541 | G38: =G33/G36 -> 32.486499 | H38: =H33/H36 -> 40.420588 | I38: =I33/I36 -> 47.189008 | J38: =J33/J36 -> 51.60054 | ... L38: =L33/L36 -> 55.73881
B39: EPS Growth % | D39: =D38/C38-1 -> 0.090076189 | E39: =E38/D38-1 -> 0.18332521 | F39: =F38/E38-1 -> -0.015097286 | G39: =G38/F38-1 -> 0.13290442 | H39: =H38/G38-1 -> 0.24422727 | I39: =I38/H38-1 -> 0.16744981 | J39: =J38/I38-1 -> 0.093486431 | K39: =K38/J38-1 -> 0.0055153183 | L39: =L38/K38-1 -> 0.074273236
B41: Dividend Per Share | C41: =IFERROR('Data Sheet'!B31/'Historical FS'!C36,0) -> 12.077755 | D41: =IFERROR('Data Sheet'!C31/'Historical FS'!D36,0) -> 12.824833 | E41: =IFERROR('Data Sheet'!D31/'Historical FS'!E36,0) -> 21.669337 | F41: =IFERROR('Data Sheet'!E31/'Historical FS'!F36,0) -> 21.109433 | G41: =IFERROR('Data Sheet'!F31/'Historical FS'!G36,0) -> 17.438366 | H41: =IFERROR('Data Sheet'!G31/'Historical FS'!H36,0) -> 26.91952 | I41: =IFERROR('Data Sheet'!H31/'Historical FS'!I36,0) -> 30.92115 | J41: =IFERROR('Data Sheet'!I31/'Historical FS'!J36,0) -> 33.913127 | ... L41: =IFERROR('Data Sheet'!K31/'Historical FS'!L36,0) -> 42.924422
B42: Dividend Payout Ratio | C42: =IFERROR(C41/C38,0) -> 0.53509499 | D42: =IFERROR(D41/D38,0) -> 0.52124215 | E42: =IFERROR(E41/E38,0) -> 0.74426797 | F42: =IFERROR(F41/F38,0) -> 0.73615102 | G42: =IFERROR(G41/G38,0) -> 0.53678809 | H42: =IFERROR(H41/H38,0) -> 0.66598537 | I42: =IFERROR(I41/I38,0) -> 0.6552617 | J42: =IFERROR(J41/J38,0) -> 0.65722427 | ... L42: =IFERROR(L41/L38,0) -> 0.77009935
B44: Retained Earning | C44: =IFERROR(IF(C38>C41,1-C42,0),0) -> 0.46490501 | D44: =IFERROR(IF(D38>D41,1-D42,0),0) -> 0.47875785 | E44: =IFERROR(IF(E38>E41,1-E42,0),0) -> 0.25573203 | F44: =IFERROR(IF(F38>F41,1-F42,0),0) -> 0.26384898 | G44: =IFERROR(IF(G38>G41,1-G42,0),0) -> 0.46321191 | H44: =IFERROR(IF(H38>H41,1-H42,0),0) -> 0.33401463 | I44: =IFERROR(IF(I38>I41,1-I42,0),0) -> 0.3447383 | J44: =IFERROR(IF(J38>J41,1-J42,0),0) -> 0.34277573 | ... L44: =IFERROR(IF(L38>L41,1-L42,0),0) -> 0.22990065
A46: # | B46: Balance Sheet
B47: Equity Share Capital | C47: =IFERROR('Data Sheet'!B57,0) -> 1144 | D47: =IFERROR('Data Sheet'!C57,0) -> 1144 | E47: =IFERROR('Data Sheet'!D57,0) -> 1088 | F47: =IFERROR('Data Sheet'!E57,0) -> 2170 | G47: =IFERROR('Data Sheet'!F57,0) -> 2122 | H47: =IFERROR('Data Sheet'!G57,0) -> 2124 | I47: =IFERROR('Data Sheet'!H57,0) -> 2098 | J47: =IFERROR('Data Sheet'!I57,0) -> 2069 | ... L47: =IFERROR('Data Sheet'!K57,0) -> 2073 | M47: =L47 -> 2073
B48: Reserves | C48: =IFERROR('Data Sheet'!B58,0) -> 60600 | D48: =IFERROR('Data Sheet'!C58,0) -> 67838 | E48: =IFERROR('Data Sheet'!D58,0) -> 63835 | F48: =IFERROR('Data Sheet'!E58,0) -> 62778 | G48: =IFERROR('Data Sheet'!F58,0) -> 63328 | H48: =IFERROR('Data Sheet'!G58,0) -> 74227 | I48: =IFERROR('Data Sheet'!H58,0) -> 73252 | J48: =IFERROR('Data Sheet'!I58,0) -> 73338 | ... L48: =IFERROR('Data Sheet'!K58,0) -> 93745 | M48: =IFERROR(L48+M33,0) -> 121748
B49: Borrowings | C49: =IFERROR('Data Sheet'!B59,0) -> 0 | D49: =IFERROR('Data Sheet'!C59,0) -> 0 | E49: =IFERROR('Data Sheet'!D59,0) -> 0 | F49: =IFERROR('Data Sheet'!E59,0) -> 0 | G49: =IFERROR('Data Sheet'!F59,0) -> 4633 | H49: =IFERROR('Data Sheet'!G59,0) -> 5325 | I49: =IFERROR('Data Sheet'!H59,0) -> 5474 | J49: =IFERROR('Data Sheet'!I59,0) -> 8299 | ... L49: =IFERROR('Data Sheet'!K59,0) -> 8227 | M49: =L49 -> 8227
B50: Other Liabilities | C50: =IFERROR('Data Sheet'!B60,0) -> 13354 | D50: =IFERROR('Data Sheet'!C60,0) -> 14166 | E50: =IFERROR('Data Sheet'!D60,0) -> 14426 | F50: =IFERROR('Data Sheet'!E60,0) -> 19118 | G50: =IFERROR('Data Sheet'!F60,0) -> 21717 | H50: =IFERROR('Data Sheet'!G60,0) -> 25835 | I50: =IFERROR('Data Sheet'!H60,0) -> 35905 | J50: =IFERROR('Data Sheet'!I60,0) -> 40890 | ... L50: =IFERROR('Data Sheet'!K60,0) -> 43750 | M50: =IFERROR(L50*(1+M7),0) -> 46483.335
B51: Total Liability | C51: =IFERROR('Data Sheet'!B61,0) -> 75098 | D51: =IFERROR('Data Sheet'!C61,0) -> 83148 | E51: =IFERROR('Data Sheet'!D61,0) -> 79349 | F51: =IFERROR('Data Sheet'!E61,0) -> 84066 | G51: =IFERROR('Data Sheet'!F61,0) -> 91800 | H51: =IFERROR('Data Sheet'!G61,0) -> 107511 | I51: =IFERROR('Data Sheet'!H61,0) -> 116729 | J51: =IFERROR('Data Sheet'!I61,0) -> 124596 | ... L51: =IFERROR('Data Sheet'!K61,0) -> 147795 | M51: =SUM(M47:M50) -> 178531.33
B53: Fixed Assets Net Block | C53: =IFERROR('Data Sheet'!B62,0) -> 13386 | D53: =IFERROR('Data Sheet'!C62,0) -> 14179 | E53: =IFERROR('Data Sheet'!D62,0) -> 12574 | F53: =IFERROR('Data Sheet'!E62,0) -> 15710 | G53: =IFERROR('Data Sheet'!F62,0) -> 23789 | H53: =IFERROR('Data Sheet'!G62,0) -> 25505 | I53: =IFERROR('Data Sheet'!H62,0) -> 25800 | J53: =IFERROR('Data Sheet'!I62,0) -> 29225 | ... L53: =IFERROR('Data Sheet'!K62,0) -> 30961
B54: Capital Work in Progress | C54: =IFERROR('Data Sheet'!B63,0) -> 960 | D54: =IFERROR('Data Sheet'!C63,0) -> 1365 | E54: =IFERROR('Data Sheet'!D63,0) -> 1606 | F54: =IFERROR('Data Sheet'!E63,0) -> 1388 | G54: =IFERROR('Data Sheet'!F63,0) -> 954 | H54: =IFERROR('Data Sheet'!G63,0) -> 922 | I54: =IFERROR('Data Sheet'!H63,0) -> 416 | J54: =IFERROR('Data Sheet'!I63,0) -> 288 | ... L54: =IFERROR('Data Sheet'!K63,0) -> 814
B55: Investments | C55: =IFERROR('Data Sheet'!B64,0) -> 1892 | D55: =IFERROR('Data Sheet'!C64,0) -> 16423 | E55: =IFERROR('Data Sheet'!D64,0) -> 12163 | F55: =IFERROR('Data Sheet'!E64,0) -> 11261 | G55: =IFERROR('Data Sheet'!F64,0) -> 8792 | H55: =IFERROR('Data Sheet'!G64,0) -> 14205 | I55: =IFERROR('Data Sheet'!H64,0) -> 20324 | J55: =IFERROR('Data Sheet'!I64,0) -> 19478 | ... L55: =IFERROR('Data Sheet'!K64,0) -> 23541
B56: Other Assets | C56: =IFERROR('Data Sheet'!B65-SUM('Data Sheet'!B67:B69),0) -> 14833 | D56: =IFERROR('Data Sheet'!C65-SUM('Data Sheet'!C67:C69),0) -> 16234 | E56: =IFERROR('Data Sheet'!D65-SUM('Data Sheet'!D67:D69),0) -> 20046 | F56: =IFERROR('Data Sheet'!E65-SUM('Data Sheet'!E67:E69),0) -> 21312 | G56: =IFERROR('Data Sheet'!F65-SUM('Data Sheet'!F67:F69),0) -> 21129 | H56: =IFERROR('Data Sheet'!G65-SUM('Data Sheet'!G67:G69),0) -> 22871 | I56: =IFERROR('Data Sheet'!H65-SUM('Data Sheet'!H67:H69),0) -> 30019 | J56: =IFERROR('Data Sheet'!I65-SUM('Data Sheet'!I67:I69),0) -> 38008 | ... L56: =IFERROR('Data Sheet'!K65-SUM('Data Sheet'!K67:K69),0) -> 36866
B57: Total Non Assets | C57: =SUM(C53:C56) -> 31071 | D57: =SUM(D53:D56) -> 48201 | E57: =SUM(E53:E56) -> 46389 | F57: =SUM(F53:F56) -> 49671 | G57: =SUM(G53:G56) -> 54664 | H57: =SUM(H53:H56) -> 63503 | I57: =SUM(I53:I56) -> 76559 | J57: =SUM(J53:J56) -> 86999 | ... L57: =SUM(L53:L56) -> 92182
...

Sheet Ratio Analysis
B2: ="Ratio Analysis - "&'Data Sheet'!B1 -> Ratio Analysis - INFOSYS LTD
B3: Years | C3: ='Data Sheet'!B16 -> 42460 | D3: ='Data Sheet'!C16 -> 42825 | E3: ='Data Sheet'!D16 -> 43190 | F3: ='Data Sheet'!E16 -> 43555 | G3: ='Data Sheet'!F16 -> 43921 | H3: ='Data Sheet'!G16 -> 44286 | I3: ='Data Sheet'!H16 -> 44651 | J3: ='Data Sheet'!I16 -> 45016 | ... L3: ='Data Sheet'!K16 -> 45747 | M3: Trend | N3: Mean | O3: Median
B5: SalesGrowth | C5: - | D5: =IFERROR('Historical FS'!D7,0) -> 0.09677936 | E5: =IFERROR('Historical FS'!E7,0) -> 0.029758776 | F5: =IFERROR('Historical FS'!F7,0) -> 0.1723292 | G5: =IFERROR('Historical FS'!G7,0) -> 0.098167523 | H5: =IFERROR('Historical FS'!H7,0) -> 0.10662951 | I5: =IFERROR('Historical FS'!I7,0) -> 0.21069552 | J5: =IFERROR('Historical FS'!J7,0) -> 0.20655864 | K5: =IFERROR('Historical FS'!K7,0) -> 0.047033734 | L5: =IFERROR('Historical FS'!L7,0) -> 0.060649444 | N5: =IFERROR(AVERAGE(D5:L5,),0) -> 0.10286017 | O5: =MEDIAN(C5:L5) -> 0.098167523
B6: EBITDA Growth | C6: - | D6: =IFERROR('Historical FS'!D18/'Historical FS'!C18-1,0) -> 0.089290942 | E6: =IFERROR('Historical FS'!E18/'Historical FS'!D18-1,0) -> 0.01171791 | F6: =IFERROR('Historical FS'!F18/'Historical FS'!E18-1,0) -> 0.071618319 | G6: =IFERROR('Historical FS'!G18/'Historical FS'!F18-1,0) -> 0.10396629 | H6: =IFERROR('Historical FS'!H18/'Historical FS'!G18-1,0) -> 0.25248125 | I6: =IFERROR('Historical FS'!I18/'Historical FS'!H18-1,0) -> 0.12915486 | J6: =IFERROR('Historical FS'!J18/'Historical FS'!I18-1,0) -> 0.11555683 | K6: =IFERROR('Historical FS'!K18/'Historical FS'!J18-1,0) -> 0.03686308 | L6: =IFERROR('Historical FS'!L18/'Historical FS'!K18-1,0) -> 0.077172272 | N6: =IFERROR(AVERAGE(D6:L6,),0) -> 0.088782175 | O6: =MEDIAN(C6:L6) -> 0.089290942
B7: EBIT Growth | C7: - | D7: =IFERROR('Historical FS'!D27/'Historical FS'!C27-1,0) -> 0.082010243 | E7: =IFERROR('Historical FS'!E27/'Historical FS'!D27-1,0) -> 0.0034317496 | F7: =IFERROR('Historical FS'!F27/'Historical FS'!E27-1,0) -> 0.070758889 | G7: =IFERROR('Historical FS'!G27/'Historical FS'!F27-1,0) -> 0.057547222 | H7: =IFERROR('Historical FS'!H27/'Historical FS'!G27-1,0) -> 0.27197459 | I7: =IFERROR('Historical FS'!I27/'Historical FS'!H27-1,0) -> 0.13869898 | J7: =IFERROR('Historical FS'!J27/'Historical FS'!I27-1,0) -> 0.10088082 | K7: =IFERROR('Historical FS'!K27/'Historical FS'!J27-1,0) -> 0.021423206 | L7: =IFERROR('Historical FS'!L27/'Historical FS'!K27-1,0) -> 0.087316558 | N7: =IFERROR(AVERAGE(D7:L7,),0) -> 0.083404226 | O7: =MEDIAN(C7:L7) -> 0.082010243
B8: Net Profit Growth | C8: - | D8: =IFERROR('Historical FS'!D33/'Historical FS'!C33-1,0) -> 0.090076189 | E8: =IFERROR('Historical FS'!E33/'Historical FS'!D33-1,0) -> 0.125188 | F8: =IFERROR('Historical FS'!F33/'Historical FS'!E33-1,0) -> -0.014939456 | G8: =IFERROR('Historical FS'!G33/'Historical FS'!F33-1,0) -> 0.10440613 | H8: =IFERROR('Historical FS'!H33/'Historical FS'!G33-1,0) -> 0.24472391 | I8: =IFERROR('Historical FS'!I33/'Historical FS'!H33-1,0) -> 0.15265358 | J8: =IFERROR('Historical FS'!J33/'Historical FS'!I33-1,0) -> 0.078383961 | K8: =IFERROR('Historical FS'!K33/'Historical FS'!J33-1,0) -> 0.0060727799 | L8: =IFERROR('Historical FS'!L33/'Historical FS'!K33-1,0) -> 0.074894368 | N8: =IFERROR(AVERAGE(D8:L8,),0) -> 0.086145947 | O8: =MEDIAN(C8:L8) -> 0.090076189
B10: Gross Margin | C10: =IFERROR('Historical FS'!C13,0) -> 0.35151583 | D10: =IFERROR('Historical FS'!D13,0) -> 0.34862158 | E10: =IFERROR('Historical FS'!E13,0) -> 0.34212019 | F10: =IFERROR('Historical FS'!F13,0) -> 0.32934986 | G10: =IFERROR('Historical FS'!G13,0) -> 0.31479993 | H10: =IFERROR('Historical FS'!H13,0) -> 0.31831754 | I10: =IFERROR('Historical FS'!I13,0) -> 0.30271043 | J10: =IFERROR('Historical FS'!J13,0) -> 0.28539794 | ... L10: =IFERROR('Historical FS'!L13,0) -> 0.28471072 | N10: =IFERROR(AVERAGE(C10:L10),0) -> 0.31615292 | O10: =MEDIAN(C10:L10) -> 0.31655873
B11: EBITDA Margin | C11: =IFERROR('Historical FS'!C19,0) -> 0.2735222 | D11: =IFERROR('Historical FS'!D19,0) -> 0.27165469 | E11: =IFERROR('Historical FS'!E19,0) -> 0.26689544 | F11: =IFERROR('Historical FS'!F19,0) -> 0.24396734 | G11: =IFERROR('Historical FS'!G19,0) -> 0.24525559 | H11: =IFERROR('Historical FS'!H19,0) -> 0.27757982 | I11: =IFERROR('Historical FS'!I19,0) -> 0.25888475 | J11: =IFERROR('Historical FS'!J19,0) -> 0.23935898 | ... L11: =IFERROR('Historical FS'!L19,0) -> 0.24072642 | N11: =IFERROR(AVERAGE(C11:L11),0) -> 0.25548792 | O11: =MEDIAN(C11:L11) -> 0.25207017
B12: EBIT Margin | C12: =IFERROR(('Historical FS'!C18-'Historical FS'!C24)/'Historical FS'!C6,0) -> 0.25015615 | D12: =IFERROR(('Historical FS'!D18-'Historical FS'!D24)/'Historical FS'!D6,0) -> 0.24678757 | E12: =IFERROR(('Historical FS'!E18-'Historical FS'!E24)/'Historical FS'!E6,0) -> 0.24047815 | F12: =IFERROR(('Historical FS'!F18-'Historical FS'!F24)/'Historical FS'!F6,0) -> 0.21964318 | G12: =IFERROR(('Historical FS'!G18-'Historical FS'!G24)/'Historical FS'!G6,0) -> 0.2133912 | H12: =IFERROR(('Historical FS'!H18-'Historical FS'!H24)/'Historical FS'!H6,0) -> 0.2450633 | I12: =IFERROR(('Historical FS'!I18-'Historical FS'!I24)/'Historical FS'!I6,0) -> 0.23030886 | J12: =IFERROR(('Historical FS'!J18-'Historical FS'!J24)/'Historical FS'!J6,0) -> 0.21057186 | ... L12: =IFERROR(('Historical FS'!L18-'Historical FS'!L24)/'Historical FS'!L6,0) -> 0.21120314 | N12: =IFERROR(AVERAGE(C12:L12),0) -> 0.22741955 | O12: =MEDIAN(C12:L12) -> 0.22497602
B13: EBT Margin | C13: =IFERROR('Historical FS'!C28,0) -> 0.25015615 | D13: =IFERROR('Historical FS'!D28,0) -> 0.24678757 | E13: =IFERROR('Historical FS'!E28,0) -> 0.24047815 | F13: =IFERROR('Historical FS'!F28,0) -> 0.21964318 | G13: =IFERROR('Historical FS'!G28,0) -> 0.21151876 | H13: =IFERROR('Historical FS'!H28,0) -> 0.24312246 | I13: =IFERROR('Historical FS'!I28,0) -> 0.22866468 | J13: =IFERROR('Historical FS'!J28,0) -> 0.20863682 | ... L13: =IFERROR('Historical FS'!L28,0) -> 0.20865084 | N13: =IFERROR(AVERAGE(C13:L13),0) -> 0.22611922 | O13: =MEDIAN(C13:L13) -> 0.22415393
B14: Net Profit Margin | C14: =IFERROR('Historical FS'!C34,0) -> 0.16606076 | D14: =IFERROR('Historical FS'!D34,0) -> 0.16504585 | E14: =IFERROR('Historical FS'!E34,0) -> 0.18034089 | F14: =IFERROR('Historical FS'!F34,0) -> 0.15153311 | G14: =IFERROR('Historical FS'!G34,0) -> 0.15239396 | H14: =IFERROR('Historical FS'!H34,0) -> 0.17141094 | I14: =IFERROR('Historical FS'!I34,0) -> 0.16319333 | J14: =IFERROR('Historical FS'!J34,0) -> 0.14585704 | ... L14: =IFERROR('Historical FS'!L34,0) -> 0.14203325 | N14: =IFERROR(AVERAGE(C14:L14),0) -> 0.15780201 | O14: =MEDIAN(C14:L14) -> 0.15779365
B16: SalesExpenses%Sales | C16: =IFERROR('Historical FS'!C16,0) -> 0.077993626 | D16: =IFERROR('Historical FS'!D16,0) -> 0.076966883 | E16: =IFERROR('Historical FS'!E16,0) -> 0.075224753 | F16: =IFERROR('Historical FS'!F16,0) -> 0.085382522 | G16: =IFERROR('Historical FS'!G16,0) -> 0.069544338 | H16: =IFERROR('Historical FS'!H16,0) -> 0.040737718 | I16: =IFERROR('Historical FS'!I16,0) -> 0.043825684 | J16: =IFERROR('Historical FS'!J16,0) -> 0.04603896 | ... L16: =IFERROR('Historical FS'!L16,0) -> 0.043984294 | N16: =IFERROR(AVERAGE(C16:L16),0) -> 0.060665004 | O16: =MEDIAN(C16:L16) -> 0.058247799
B17: Depreciation%Sales | C17: =IFERROR('Historical FS'!C25,0) -> 0.023366058 | D17: =IFERROR('Historical FS'!D25,0) -> 0.024867122 | E17: =IFERROR('Historical FS'!E25,0) -> 0.026417288 | F17: =IFERROR('Historical FS'!F25,0) -> 0.024324161 | G17: =IFERROR('Historical FS'!G25,0) -> 0.031864392 | H17: =IFERROR('Historical FS'!H25,0) -> 0.032516522 | I17: =IFERROR('Historical FS'!I25,0) -> 0.028575891 | J17: =IFERROR('Historical FS'!J25,0) -> 0.028787125 | ... L17: =IFERROR('Historical FS'!L25,0) -> 0.029523284 | N17: =IFERROR(AVERAGE(C17:L17),0) -> 0.02806837 | O17: =MEDIAN(C17:L17) -> 0.028681508
B18: OperatingIncome%Sales | C18: =C12 -> 0.25015615 | D18: =D12 -> 0.24678757 | E18: =E12 -> 0.24047815 | F18: =F12 -> 0.21964318 | G18: =G12 -> 0.2133912 | H18: =H12 -> 0.2450633 | I18: =I12 -> 0.23030886 | J18: =J12 -> 0.21057186 | ... L18: =L12 -> 0.21120314 | N18: =IFERROR(AVERAGE(C18:L18),0) -> 0.22741955 | O18: =MEDIAN(C18:L18) -> 0.22497602
B20: Return on Capital Employed | C20: =IFERROR(('Historical FS'!C18-'Historical FS'!C24)/SUM('Historical FS'!C47:C49),0) -> 0.25298005 | D20: =IFERROR(('Historical FS'!D18-'Historical FS'!D24)/SUM('Historical FS'!D47:D49),0) -> 0.24500594 | E20: =IFERROR(('Historical FS'!E18-'Historical FS'!E24)/SUM('Historical FS'!E47:E49),0) -> 0.26121713 | F20: =IFERROR(('Historical FS'!F18-'Historical FS'!F24)/SUM('Historical FS'!F47:F49),0) -> 0.27959291 | G20: =IFERROR(('Historical FS'!G18-'Historical FS'!G24)/SUM('Historical FS'!G47:G49),0) -> 0.27644365 | H20: =IFERROR(('Historical FS'!H18-'Historical FS'!H24)/SUM('Historical FS'!H47:H49),0) -> 0.30145943 | I20: =IFERROR(('Historical FS'!I18-'Historical FS'!I24)/SUM('Historical FS'!I47:I49),0) -> 0.34661734 | J20: =IFERROR(('Historical FS'!J18-'Historical FS'!J24)/SUM('Historical FS'!J47:J49),0) -> 0.3692089 | ... L20: =IFERROR(('Historical FS'!L18-'Historical FS'!L24)/SUM('Historical FS'!L47:L49),0) -> 0.33085684 | N20: =IFERROR(AVERAGE(C20:L20),0) -> 0.29924519 | O20: =MEDIAN(C20:L20) -> 0.29052617
B21: Retained Earnings% | C21: ='Historical FS'!C44 -> 0.46490501 | D21: ='Historical FS'!D44 -> 0.47875785 | E21: ='Historical FS'!E44 -> 0.25573203 | F21: ='Historical FS'!F44 -> 0.26384898 | G21: ='Historical FS'!G44 -> 0.46321191 | H21: ='Historical FS'!H44 -> 0.33401463 | I21: ='Historical FS'!I44 -> 0.3447383 | J21: ='Historical FS'!J44 -> 0.34277573 | ... L21: ='Historical FS'!L44 -> 0.22990065 | N21: =IFERROR(AVERAGE(C21:L21),0) -> 0.32932122 | O21: =MEDIAN(C21:L21) -> 0.33839518
B22: Return on Equity% | C22: =IFERROR(('Historical FS'!C33)/SUM('Historical FS'!C47:C48),0) -> 0.16793535 | D22: =IFERROR(('Historical FS'!D33)/SUM('Historical FS'!D47:D48),0) -> 0.16385434 | E22: =IFERROR(('Historical FS'!E33)/SUM('Historical FS'!E47:E48),0) -> 0.1958936 | F22: =IFERROR(('Historical FS'!F33)/SUM('Historical FS'!F47:F48),0) -> 0.19289278 | G22: =IFERROR(('Historical FS'!G33)/SUM('Historical FS'!G47:G48),0) -> 0.21139801 | H22: =IFERROR(('Historical FS'!H33)/SUM('Historical FS'!H47:H48),0) -> 0.22556352 | I22: =IFERROR(('Historical FS'!I33)/SUM('Historical FS'!I47:I48),0) -> 0.26345056 | J22: =IFERROR(('Historical FS'!J33)/SUM('Historical FS'!J47:J48),0) -> 0.28388611 | ... L22: =IFERROR(('Historical FS'!L33)/SUM('Historical FS'!L47:L48),0) -> 0.24160387 | N22: =IFERROR(AVERAGE(C22:L22),0) -> 0.21908946 | O22: =MEDIAN(C22:L22) -> 0.21848076
B23: Self Sustained Growth Rate | C23: =C21*C22 -> 0.078073983 | D23: =D21*D22 -> 0.078446551 | E23: =E21*E22 -> 0.050096268 | F23: =F21*F22 -> 0.050894562 | G23: =G21*G22 -> 0.097922078 | H23: =H21*H22 -> 0.075341515 | I23: =I21*I22 -> 0.0908215 | J23: =J21*J22 -> 0.097309268 | ... L23: =L21*L22 -> 0.055544887 | N23: =IFERROR(AVERAGE(C23:L23),0) -> 0.070263846 | O23: =MEDIAN(C23:L23) -> 0.076707749
B24: Interest Coverage Ratio | C24: =IFERROR(('Historical FS'!C18-'Historical FS'!C24)/'Historical FS'!C21,0) -> 0 | D24: =IFERROR(('Historical FS'!D18-'Historical FS'!D24)/'Historical FS'!D21,0) -> 0 | E24: =IFERROR(('Historical FS'!E18-'Historical FS'!E24)/'Historical FS'!E21,0) -> 0 | F24: =IFERROR(('Historical FS'!F18-'Historical FS'!F24)/'Historical FS'!F21,0) -> 0 | G24: =IFERROR(('Historical FS'!G18-'Historical FS'!G24)/'Historical FS'!G21,0) -> 113.96471 | H24: =IFERROR(('Historical FS'!H18-'Historical FS'!H24)/'Historical FS'!H21,0) -> 126.26667 | I24: =IFERROR(('Historical FS'!I18-'Historical FS'!I24)/'Historical FS'!I21,0) -> 140.075 | J24: =IFERROR(('Historical FS'!J18-'Historical FS'!J24)/'Historical FS'!J21,0) -> 108.82042 | ... L24: =IFERROR(('Historical FS'!L18-'Historical FS'!L24)/'Historical FS'!L21,0) -> 82.75 | N24: =IFERROR(AVERAGE(C24:L24),0) -> 63.94236 | O24: =MEDIAN(C24:L24) -> 75.148404
B26: Debtor Turnover Ratio | C26: =IFERROR('Historical FS'!C6/'Historical FS'!C59,0) -> 5.5111209 | D26: =IFERROR('Historical FS'!D6/'Historical FS'!D59,0) -> 5.557864 | E26: =IFERROR('Historical FS'!E6/'Historical FS'!E59,0) -> 5.3661543 | F26: =IFERROR('Historical FS'!F6/'Historical FS'!F59,0) -> 5.5759763 | G26: =IFERROR('Historical FS'!G6/'Historical FS'!G59,0) -> 4.9110726 | H26: =IFERROR('Historical FS'!H6/'Historical FS'!H59,0) -> 5.207422 | I26: =IFERROR('Historical FS'!I6/'Historical FS'!I59,0) -> 5.3591065 | J26: =IFERROR('Historical FS'!J6/'Historical FS'!J59,0) -> 5.7727738 | ... L26: =IFERROR('Historical FS'!L6/'Historical FS'!L59,0) -> 5.2310803 | N26: =IFERROR(AVERAGE(C26:L26),0) -> 5.3582161 | O26: =MEDIAN(C26:L26) -> 5.3626304
B27: Creditor Turnover Ratio | C27: =IFERROR('Historical FS'!C6/'Historical FS'!C50,0) -> 4.6758275 | D27: =IFERROR('Historical FS'!D6/'Historical FS'!D50,0) -> 4.8343922 | E27: =IFERROR('Historical FS'!E6/'Historical FS'!E50,0) -> 4.8885346 | F27: =IFERROR('Historical FS'!F6/'Historical FS'!F50,0) -> 4.3244586 | G27: =IFERROR('Historical FS'!G6/'Historical FS'!G50,0) -> 4.1806419 | H27: =IFERROR('Historical FS'!H6/'Historical FS'!H50,0) -> 3.8889878 | I27: =IFERROR('Historical FS'!I6/'Historical FS'!I50,0) -> 3.3878568 | J27: =IFERROR('Historical FS'!J6/'Historical FS'!J50,0) -> 3.5893128 | ... L27: =IFERROR('Historical FS'!L6/'Historical FS'!L50,0) -> 3.7254857 | N27: =IFERROR(AVERAGE(C27:L27),0) -> 4.1254089 | O27: =MEDIAN(C27:L27) -> 4.0348149
B28: Inventory Turnover | C28: =IFERROR('Historical FS'!C6/'Historical FS'!C60,0) -> 0 | D28: =IFERROR('Historical FS'!D6/'Historical FS'!D60,0) -> 0 | E28: =IFERROR('Historical FS'!E6/'Historical FS'!E60,0) -> 0 | F28: =IFERROR('Historical FS'!F6/'Historical FS'!F60,0) -> 0 | G28: =IFERROR('Historical FS'!G6/'Historical FS'!G60,0) -> 0 | H28: =IFERROR('Historical FS'!H6/'Historical FS'!H60,0) -> 0 | I28: =IFERROR('Historical FS'!I6/'Historical FS'!I60,0) -> 0 | J28: =IFERROR('Historical FS'!J6/'Historical FS'!J60,0) -> 0 | ... L28: =IFERROR('Historical FS'!L6/'Historical FS'!L60,0) -> 0 | N28: =IFERROR(AVERAGE(C28:L28),0) -> 0 | O28: =MEDIAN(C28:L28) -> 0
B29: Fixed Asset Turnover | C29: =IFERROR('Historical FS'!C6/'Historical FS'!C53,0) -> 4.6646496 | D29: =IFERROR('Historical FS'!D6/'Historical FS'!D53,0) -> 4.8299598 | E29: =IFERROR('Historical FS'!E6/'Historical FS'!E53,0) -> 5.6085573 | F29: =IFERROR('Historical FS'!F6/'Historical FS'!F53,0) -> 5.2625716 | G29: =IFERROR('Historical FS'!G6/'Historical FS'!G53,0) -> 3.8165118 | H29: =IFERROR('Historical FS'!H6/'Historical FS'!H53,0) -> 3.939306 | I29: =IFERROR('Historical FS'!I6/'Historical FS'!I53,0) -> 4.7147674 | J29: =IFERROR('Historical FS'!J6/'Historical FS'!J53,0) -> 5.0219675 | ... L29: =IFERROR('Historical FS'!L6/'Historical FS'!L53,0) -> 5.2643648 | N29: =IFERROR(AVERAGE(C29:L29),0) -> 4.8685975 | O29: =MEDIAN(C29:L29) -> 4.9259636
B30: Capital Turnover Ratio | C30: =IFERROR('Historical FS'!C6/SUM('Historical FS'!C47:C48),0) -> 1.0112885 | D30: =IFERROR('Historical FS'!D6/SUM('Historical FS'!D47:D48),0) -> 0.99278073 | E30: =IFERROR('Historical FS'!E6/SUM('Historical FS'!E47:E48),0) -> 1.0862406 | F30: =IFERROR('Historical FS'!F6/SUM('Historical FS'!F47:F48),0) -> 1.2729414 | G30: =IFERROR('Historical FS'!G6/SUM('Historical FS'!G47:G48),0) -> 1.3871811 | H30: =IFERROR('Historical FS'!H6/SUM('Historical FS'!H47:H48),0) -> 1.3159225 | I30: =IFERROR('Historical FS'!I6/SUM('Historical FS'!I47:I48),0) -> 1.6143464 | J30: =IFERROR('Historical FS'!J6/SUM('Historical FS'!J47:J48),0) -> 1.9463312 | ... L30: =IFERROR('Historical FS'!L6/SUM('Historical FS'!L47:L48),0) -> 1.7010374 | N30: =IFERROR(AVERAGE(C30:L30),0) -> 1.4072021 | O30: =MEDIAN(C30:L30) -> 1.3515518
B32: Debtor Days | C32: =IFERROR(365/C26,0) -> 66.229721 | D32: =IFERROR(365/D26,0) -> 65.672712 | E32: =IFERROR(365/E26,0) -> 68.018916 | F32: =IFERROR(365/F26,0) -> 65.459389 | G32: =IFERROR(365/G26,0) -> 74.321849 | H32: =IFERROR(365/H26,0) -> 70.092265 | I32: =IFERROR(365/I26,0) -> 68.108368 | J32: =IFERROR(365/J26,0) -> 63.227837 | ... L32: =IFERROR(365/L26,0) -> 69.775262 | N32: =IFERROR(AVERAGE(C32:L32),0) -> 68.262133 | O32: =MEDIAN(C32:L32) -> 68.063642
B33: Payable Days | C33: =IFERROR(365/C27,0) -> 78.06105 | D33: =IFERROR(365/D27,0) -> 75.500701 | E33: =IFERROR(365/E27,0) -> 74.664502 | F33: =IFERROR(365/F27,0) -> 84.403629 | G33: =IFERROR(365/G27,0) -> 87.307167 | H33: =IFERROR(365/H27,0) -> 93.854756 | I33: =IFERROR(365/I27,0) -> 107.73773 | J33: =IFERROR(365/J27,0) -> 101.69078 | ... L33: =IFERROR(365/L27,0) -> 97.973802 | N33: =IFERROR(AVERAGE(C33:L33),0) -> 89.830496 | O33: =MEDIAN(C33:L33) -> 90.580961
B34: Inventory Days | C34: =IFERROR(365/C28,0) -> 0 | D34: =IFERROR(365/D28,0) -> 0 | E34: =IFERROR(365/E28,0) -> 0 | F34: =IFERROR(365/F28,0) -> 0 | G34: =IFERROR(365/G28,0) -> 0 | H34: =IFERROR(365/H28,0) -> 0 | I34: =IFERROR(365/I28,0) -> 0 | J34: =IFERROR(365/J28,0) -> 0 | ... L34: =IFERROR(365/L28,0) -> 0 | N34: =IFERROR(AVERAGE(C34:L34),0) -> 0 | O34: =MEDIAN(C34:L34) -> 0
B35: Cash Conversion Cycle | C35: =IFERROR(SUM(C32,C34)-C33,0) -> -11.831329 | D35: =IFERROR(SUM(D32,D34)-D33,0) -> -9.827989 | E35: =IFERROR(SUM(E32,E34)-E33,0) -> -6.6455858 | F35: =IFERROR(SUM(F32,F34)-F33,0) -> -18.944239 | G35: =IFERROR(SUM(G32,G34)-G33,0) -> -12.985318 | H35: =IFERROR(SUM(H32,H34)-H33,0) -> -23.762491 | I35: =IFERROR(SUM(I32,I34)-I33,0) -> -39.62936 | J35: =IFERROR(SUM(J32,J34)-J33,0) -> -38.462938 | ... L35: =IFERROR(SUM(L32,L34)-L33,0) -> -28.19854 | N35: =IFERROR(AVERAGE(C35:L35),0) -> -21.568364 | O35: =MEDIAN(C35:L35) -> -21.353365
B37: CFO/Sales | C37: =IFERROR('Historical FS'!C78/'Historical FS'!C6,0) -> 0.11526081 | D37: =IFERROR('Historical FS'!D78/'Historical FS'!D6,0) -> -0.077229718 | E37: =IFERROR('Historical FS'!E78/'Historical FS'!E6,0) -> 0.2528998 | F37: =IFERROR('Historical FS'!F78/'Historical FS'!F6,0) -> 0.16638645 | G37: =IFERROR('Historical FS'!G78/'Historical FS'!G6,0) -> 0.15755967 | H37: =IFERROR('Historical FS'!H78/'Historical FS'!H6,0) -> 0.16540927 | I37: =IFERROR('Historical FS'!I78/'Historical FS'!I6,0) -> 0.1313373 | J37: =IFERROR('Historical FS'!J78/'Historical FS'!J6,0) -> 0.10255711 | ... L37: =IFERROR('Historical FS'!L78/'Historical FS'!L6,0) -> 0.20574882 | N37: =IFERROR(AVERAGE(C37:L37),0) -> 0.1317769 | O37: =MEDIAN(C37:L37) -> 0.14444848
B38: CFO/Total Assets | C38: =IFERROR('Historical FS'!C78/'Historical FS'!C64,0) -> 0.095834776 | D38: =IFERROR('Historical FS'!D78/'Historical FS'!D64,0) -> -0.063609467 | E38: =IFERROR('Historical FS'!E78/'Historical FS'!E64,0) -> 0.22476654 | F38: =IFERROR('Historical FS'!F78/'Historical FS'!F64,0) -> 0.16363334 | G38: =IFERROR('Historical FS'!G78/'Historical FS'!G64,0) -> 0.15582789 | H38: =IFERROR('Historical FS'!H78/'Historical FS'!H64,0) -> 0.15457953 | I38: =IFERROR('Historical FS'!I78/'Historical FS'!I64,0) -> 0.13686402 | J38: =IFERROR('Historical FS'!J78/'Historical FS'!J64,0) -> 0.12080645 | ... L38: =IFERROR('Historical FS'!L78/'Historical FS'!L64,0) -> 0.22690213 | N38: =IFERROR(AVERAGE(C38:L38),0) -> 0.13250621 | O38: =MEDIAN(C38:L38) -> 0.14572177
B39: CFO/Total Debt | C39: =IFERROR('Historical FS'!C78/'Historical FS'!C49,0) -> 0 | D39: =IFERROR('Historical FS'!D78/'Historical FS'!D49,0) -> 0 | E39: =IFERROR('Historical FS'!E78/'Historical FS'!E49,0) -> 0 | F39: =IFERROR('Historical FS'!F78/'Historical FS'!F49,0) -> 0 | G39: =IFERROR('Historical FS'!G78/'Historical FS'!G49,0) -> 3.0876322 | H39: =IFERROR('Historical FS'!H78/'Historical FS'!H49,0) -> 3.120939 | I39: =IFERROR('Historical FS'!I78/'Historical FS'!I49,0) -> 2.9185239 | J39: =IFERROR('Historical FS'!J78/'Historical FS'!J49,0) -> 1.8137125 | ... L39: =IFERROR('Historical FS'!L78/'Historical FS'!L49,0) -> 4.0762125 | N39: =IFERROR(AVERAGE(C39:L39),0) -> 1.681568 | O39: =MEDIAN(C39:L39) -> 1.8061863
O44: ="Ratio Analysis - "&'Data Sheet'!O43 -> Ratio Analysis -
O45: Years | P45: ='Data Sheet'!O58 -> 0 | Q45: ='Data Sheet'!P58 -> 0 | R45: ='Data Sheet'!Q58 -> 0 | S45: ='Data Sheet'!R58 -> 0 | T45: ='Data Sheet'!S58 -> 0 | U45: ='Data Sheet'!T58 -> 0 | V45: ='Data Sheet'!U58 -> 0 | W45: ='Data Sheet'!V58 -> 0 | ... Y45: ='Data Sheet'!X58 -> 0 | Z45: Trend | AA45: Mean | AB45: Median
O47: SalesGrowth | P47: - | Q47: =IFERROR('Historical FS'!Q49,0) -> 0 | R47: =IFERROR('Historical FS'!R49,0) -> 0 | S47: =IFERROR('Historical FS'!S49,0) -> 0 | T47: =IFERROR('Historical FS'!T49,0) -> 0 | U47: =IFERROR('Historical FS'!U49,0) -> 0 | V47: =IFERROR('Historical FS'!V49,0) -> 0 | W47: =IFERROR('Historical FS'!W49,0) -> 0 | X47: =IFERROR('Historical FS'!X49,0) -> 0 | Y47: =IFERROR('Historical FS'!Y49,0) -> 0 | AA47: =IFERROR(AVERAGE(Q47:Y47,),0) -> 0 | AB47: =MEDIAN(P47:Y47) -> 0
O48: EBITDA Growth | P48: - | Q48: =IFERROR('Historical FS'!Q60/'Historical FS'!P60-1,0) -> 0 | R48: =IFERROR('Historical FS'!R60/'Historical FS'!Q60-1,0) -> 0 | S48: =IFERROR('Historical FS'!S60/'Historical FS'!R60-1,0) -> 0 | T48: =IFERROR('Historical FS'!T60/'Historical FS'!S60-1,0) -> 0 | U48: =IFERROR('Historical FS'!U60/'Historical FS'!T60-1,0) -> 0 | V48: =IFERROR('Historical FS'!V60/'Historical FS'!U60-1,0) -> 0 | W48: =IFERROR('Historical FS'!W60/'Historical FS'!V60-1,0) -> 0 | X48: =IFERROR('Historical FS'!X60/'Historical FS'!W60-1,0) -> 0 | Y48: =IFERROR('Historical FS'!Y60/'Historical FS'!X60-1,0) -> 0 | AA48: =IFERROR(AVERAGE(Q48:Y48,),0) -> 0 | AB48: =MEDIAN(P48:Y48) -> 0
O49: EBIT Growth | P49: - | Q49: =IFERROR('Historical FS'!Q69/'Historical FS'!P69-1,0) -> 0 | R49: =IFERROR('Historical FS'!R69/'Historical FS'!Q69-1,0) -> 0 | S49: =IFERROR('Historical FS'!S69/'Historical FS'!R69-1,0) -> 0 | T49: =IFERROR('Historical FS'!T69/'Historical FS'!S69-1,0) -> 0 | U49: =IFERROR('Historical FS'!U69/'Historical FS'!T69-1,0) -> 0 | V49: =IFERROR('Historical FS'!V69/'Historical FS'!U69-1,0) -> 0 | W49: =IFERROR('Historical FS'!W69/'Historical FS'!V69-1,0) -> 0 | X49: =IFERROR('Historical FS'!X69/'Historical FS'!W69-1,0) -> 0 | Y49: =IFERROR('Historical FS'!Y69/'Historical FS'!X69-1,0) -> 0 | AA49: =IFERROR(AVERAGE(Q49:Y49,),0) -> 0 | AB49: =MEDIAN(P49:Y49) -> 0
