Workbook

Sheet DCF>

Sheet WACC
B2: Weighted Average Cost of Capital
B4: All figures are in INR unless stated otherwise.
B6: Peer Comps
G7: Debt/ | H7: Debt/ | I7: Levered | J7: Unlevered
B8: Name | C8: Country | D8: Total Debt | E8: Total Equity | F8: Tax Rate 1 | G8: Equity | H8: Capital | I8: Beta 2 | J8: Beta 3
B10: Infosys | C10: India | D10: ='Beta- Comparison'!F3 -> 8796 | E10: ='Beta- Comparison'!E3 -> 530607.37 | F10: 0.27 | G10: =D10/E10 -> 0.016577229 | H10: =D10/SUM(D10:E10) -> 0.016306906 | I10: ='Beta - Regression'!K10 -> 0.83494575 | J10: =I10/(1+(1-F10)*G10) -> 0.82496257
B11: TCS | C11: India | D11: ='Beta- Comparison'!F4 -> 10932 | E11: ='Beta- Comparison'!E4 -> 925362.06 | F11: 0.27 | G11: =D11/E11 -> 0.011813754 | H11: =D11/SUM(D11:E11) -> 0.011675819 | I11: 0.6 | J11: =I11/(1+(1-F11)*G11) -> 0.59486982
B12: HCL Technologies | C12: India | D12: ='Beta- Comparison'!F5 -> 6780 | E12: ='Beta- Comparison'!E5 -> 368162.94 | F12: 0.27 | G12: =D12/E12 -> 0.018415759 | H12: =D12/SUM(D12:E12) -> 0.018082751 | I12: 0.62 | J12: =I12/(1+(1-F12)*G12) -> 0.61177559
B13: Wipro | C13: India | D13: ='Beta- Comparison'!F6 -> 16163.7 | E13: ='Beta- Comparison'!E6 -> 204936.45 | F13: 0.27 | G13: =D13/E13 -> 0.078871767 | H13: =D13/SUM(D13:E13) -> 0.073105785 | I13: 0.9 | J13: =I13/(1+(1-F13)*G13) -> 0.85100236
B14: Tech Mahindra | C14: India | D14: ='Beta- Comparison'!F7 -> 1954.4 | E14: ='Beta- Comparison'!E7 -> 130477.26 | F14: 0.27 | G14: =D14/E14 -> 0.014978855 | H14: =D14/SUM(D14:E14) -> 0.0147578 | I14: 1.06 | J14: =I14/(1+(1-F14)*G14) -> 1.0485347
E16: Average | F16: =AVERAGE(F10:F14) -> 0.27 | G16: =AVERAGE(G10:G14) -> 0.028131473 | H16: =AVERAGE(H10:H14) -> 0.026785812 | I16: =AVERAGE(I10:I14) -> 0.80298915 | J16: =AVERAGE(J10:J14) -> 0.78622901
E17: Median | F17: =MEDIAN(F10:F14) -> 0.27 | G17: =MEDIAN(G10:G14) -> 0.016577229 | H17: =MEDIAN(H10:H14) -> 0.016306906 | I17: =MEDIAN(I10:I14) -> 0.83494575 | J17: =MEDIAN(J10:J14) -> 0.82496257
B20: Cost of Debt | G20: Cost of Equity
B22: Pre-tax Cost of Debt | E22: =284/8796 -> 0.032287403 | G22: Risk Free Rate | J22: 0.0672
B23: Tax Rate | E23: =F17 -> 0.27 | G23: Equity Risk Premium | J23: ='Market Return'!G6-WACC!J22 -> 0.10509091
B24: After Tax Cost of Debt | E24: =E22*(1-E23) -> 0.023569804 | G24: Levered Beta 4 | J24: =J33 -> 0.84153757
G25: Cost of Equity | J25: =J22+J23*J24 -> 0.15563795
B28: Capital Structure | G28: Levered Beta
D30: Current | E30: Target | G30: Comps Median Unlevered Beta | J30: =J17 -> 0.82496257
B31: Total Debt | C31: =D10 -> 8796 | D31: =C31/$C$33 -> 0.016306906 | E31: =H16 -> 0.026785812 | G31: Target Debt/ Equity | J31: =E35 -> 0.027523039
B32: Market Capitalization | C32: =E10 -> 530607.37 | D32: =C32/$C$33 -> 0.98369309 | E32: =E33-E31 -> 0.97321419 | G32: Tax Rate | J32: =E23 -> 0.27
B33: Total Capitalization | C33: =SUM(C31:C32) -> 539403.37 | D33: =C33/$C$33 -> 1 | E33: =D33 -> 1 | G33: Levered Beta | J33: =J30*(1+(1-J32)*J31) -> 0.84153757
B35: Debt / Equity | D35: =D31/D32 -> 0.016577229 | E35: =E31/E32 -> 0.027523039 | G35: Weighted Average Cost of Capital
B37: 1. Tax Rate considered as Marginal Tax Rate for the country | I37: Total Cost | J37: Total Weighted
B38: 2. Levered Beta is based on 5 year monthly data | G38: Debt | I38: =E24 -> 0.023569804 | J38: =E31 -> 0.026785812
B39: 3. Unlevered Beta = Levered Beta/(1+(1-Tax Rate) x Debt/Equity) | G39: Equity | I39: =J25 -> 0.15563795 | J39: =E32 -> 0.97321419
B40: 3. Levered Beta = Unlevered Beta*(1+(1-Tax Rate) x Debt/Equity) | G40: WACC | J40: =SUMPRODUCT(I38:I39,J38:J39) -> 0.1521004

Sheet Beta- Comparison
B2: S.No. | C2: Name | D2: CMP Rs. | E2: Mar Cap Rs.Cr. | F2: Debt Rs.Cr. | G2: Debt / Eq
B3: 1 | C3: Infosys | D3: 1308.4 | E3: 530607.37 | F3: 8796 | G3: 0.11
B4: 2 | C4: TCS | D4: 2557.6 | E4: 925362.06 | F4: 10932 | G4: 0.1
B5: 3 | C5: HCL Technologies | D5: 1356.7 | E5: 368162.94 | F5: 6780 | G5: 0.1
B6: 4 | C6: Wipro | D6: 195.4 | E6: 204936.45 | F6: 16163.7 | G6: 0.19
B7: 5 | C7: Tech Mahindra | D7: 1331.7 | E7: 130477.26 | F7: 1954.4 | G7: 0.07

Sheet Beta - Regression
B2: Infosys Weekly Returns | F2: NIFTY Returns | J2: Beta Drifting | M2: Beta 1 | N2: =SLOPE(D6:D108,H6:H108) -> 0.77992767
B4: Date | C4: Closing Price | D4: Return | F4: Date | G4: Closing Price | H4: Return | J4: Levered Raw Beta | K4: =N4 -> 0.77992767 | M4: Beta 2 | N4: =N23 -> 0.77992767
B5: 45362 | C5: 1538.39 | F5: 45362 | G5: 22023.35 | J5: Raw Beta Weight | K5: 0.75
B6: 45369 | C6: 1420.56 | D6: =C6/C5-1 -> -0.076593062 | F6: 45369 | G6: 22096.75 | H6: =G6/G5-1 -> 0.0033328263 | M6: SUMMARY OUTPUT
B7: 45376 | C7: 1410.39 | D7: =C7/C6-1 -> -0.0071591485 | F7: 45376 | G7: 22326.9 | H7: =G7/G6-1 -> 0.010415559 | J7: Market Beta | K7: 1
B8: 45383 | C8: 1392.55 | D8: =C8/C7-1 -> -0.012648984 | F8: 45383 | G8: 22513.7 | H8: =G8/G7-1 -> 0.0083665892 | J8: Market Beta Weight | K8: 0.25 | M8: Regression Statistics
B9: 45390 | C9: 1397.87 | D9: =C9/C8-1 -> 0.0038203296 | F9: 45390 | G9: 22519.4 | H9: =G9/G8-1 -> 0.00025317918 | M9: Multiple R | N9: 0.37482519
B10: 45397 | C10: 1328.67 | D10: =C10/C9-1 -> -0.049503888 | F10: 45397 | G10: 22147 | H10: =G10/G9-1 -> -0.016536853 | J10: Adjusted Beta | K10: =(K4*K5)+(K7*K8) -> 0.83494575 | M10: R Square | N10: 0.14049392
B11: 45404 | C11: 1346.56 | D11: =C11/C10-1 -> 0.013464592 | F11: 45404 | G11: 22419.95 | H11: =G11/G10-1 -> 0.012324468 | M11: Adjusted R Square | N11: 0.13198396
B12: 45411 | C12: 1333.43 | D12: =C12/C11-1 -> -0.0097507723 | F12: 45411 | G12: 22475.85 | H12: =G12/G11-1 -> 0.0024933151 | M12: Standard Error | N12: 0.033521079
B13: 45418 | C13: 1341.52 | D13: =C13/C12-1 -> 0.0060670601 | F13: 45418 | G13: 22055.2 | H13: =G13/G12-1 -> -0.018715644 | M13: Observations | N13: 103
B14: 45425 | C14: 1359.17 | D14: =C14/C13-1 -> 0.013156718 | F14: 45425 | G14: 22466.1 | H14: =G14/G13-1 -> 0.018630527
B15: 45432 | C15: 1379.37 | D15: =C15/C14-1 -> 0.014862011 | F15: 45432 | G15: 22957.1 | H15: =G15/G14-1 -> 0.021855151 | M15: ANOVA
B16: 45439 | C16: 1324.58 | D16: =C16/C15-1 -> -0.039721032 | F16: 45439 | G16: 22530.7 | H16: =G16/G15-1 -> -0.018573775 | N16: df | O16: SS | P16: MS | Q16: F | R16: Significance F
B17: 45446 | C17: 1472.75 | D17: =C17/C16-1 -> 0.11186187 | F17: 45446 | G17: 23290.15 | H17: =G17/G16-1 -> 0.033707342 | M17: Regression | N17: 1 | O17: 0.01855094 | P17: 0.01855094 | Q17: 16.509349 | R17: 9.585811e-05
B18: 45453 | C18: 1429.82 | D18: =C18/C17-1 -> -0.02914955 | F18: 45453 | G18: 23465.6 | H18: =G18/G17-1 -> 0.0075332276 | M18: Residual | N18: 101 | O18: 0.11348993 | P18: 0.0011236627
B19: 45460 | C19: 1471.89 | D19: =C19/C18-1 -> 0.029423284 | F19: 45460 | G19: 23501.1 | H19: =G19/G18-1 -> 0.0015128529 | M19: Total | N19: 102 | O19: 0.13204087
B20: 45467 | C20: 1504.58 | D20: =C20/C19-1 -> 0.02220954 | F20: 45467 | G20: 24010.6 | H20: =G20/G19-1 -> 0.021679836
B21: 45474 | C21: 1582.08 | D21: =C21/C20-1 -> 0.051509391 | F21: 45474 | G21: 24323.85 | H21: =G21/G20-1 -> 0.013046321 | N21: Coefficients | O21: Standard Error | P21: t Stat | Q21: P-value | R21: Lower 95% | S21: Upper 95% | T21: Lower 95.0% | U21: Upper 95.0%
B22: 45481 | C22: 1643.83 | D22: =C22/C21-1 -> 0.039030896 | F22: 45481 | G22: 24502.15 | H22: =G22/G21-1 -> 0.0073302541 | M22: Intercept | N22: -0.001832995 | O22: 0.0033104748 | P22: -0.55369551 | Q22: 0.58101098 | R22: -0.0084000866 | S22: 0.0047340965 | T22: -0.0084000866 | U22: 0.0047340965
B23: 45488 | C23: 1721.81 | D23: =C23/C22-1 -> 0.047437995 | F23: 45488 | G23: 24530.9 | H23: =G23/G22-1 -> 0.0011733664 | M23: X Variable 1 | N23: 0.77992767 | O23: 0.19195054 | P23: 4.0631699 | Q23: 9.585811e-05 | R23: 0.39914942 | S23: 1.1607059 | T23: 0.39914942 | U23: 1.1607059
B24: 45495 | C24: 1804.35 | D24: =C24/C23-1 -> 0.047937926 | F24: 45495 | G24: 24834.85 | H24: =G24/G23-1 -> 0.012390495
B25: 45502 | C25: 1748.94 | D25: =C25/C24-1 -> -0.03070912 | F25: 45502 | G25: 24717.7 | H25: =G25/G24-1 -> -0.0047171616
B26: 45509 | C26: 1700.49 | D26: =C26/C25-1 -> -0.027702494 | F26: 45509 | G26: 24367.5 | H26: =G26/G25-1 -> -0.014167985
B27: 45516 | C27: 1785.19 | D27: =C27/C26-1 -> 0.049809173 | F27: 45516 | G27: 24541.15 | H27: =G27/G26-1 -> 0.0071262953
B28: 45523 | C28: 1788.22 | D28: =C28/C27-1 -> 0.0016972983 | F28: 45523 | G28: 24823.15 | H28: =G28/G27-1 -> 0.011490904
B29: 45530 | C29: 1866.58 | D29: =C29/C28-1 -> 0.043820112 | F29: 45530 | G29: 25235.9 | H29: =G29/G28-1 -> 0.016627624
B30: 45537 | C30: 1826.39 | D30: =C30/C29-1 -> -0.021531357 | F30: 45537 | G30: 24852.15 | H30: =G30/G29-1 -> -0.015206511
B31: 45544 | C31: 1866.96 | D31: =C31/C30-1 -> 0.022213218 | F31: 45544 | G31: 25356.5 | H31: =G31/G30-1 -> 0.020294019
B32: 45551 | C32: 1830.13 | D32: =C32/C31-1 -> -0.019727257 | F32: 45551 | G32: 25790.95 | H32: =G32/G31-1 -> 0.017133674
B33: 45558 | C33: 1831.09 | D33: =C33/C32-1 -> 0.0005245529 | F33: 45558 | G33: 26178.95 | H33: =G33/G32-1 -> 0.015044037
B34: 45565 | C34: 1842.04 | D34: =C34/C33-1 -> 0.0059800447 | F34: 45565 | G34: 25014.6 | H34: =G34/G33-1 -> -0.044476574
B35: 45572 | C35: 1858.32 | D35: =C35/C34-1 -> 0.0088380274 | F35: 45572 | G35: 24964.25 | H35: =G35/G34-1 -> -0.0020128245
... B108: 46083 | C108: 1308.4 | D108: =C108/C107-1 -> 0.0063841243 | F108: 46083 | G108: 24450.45 | H108: =G108/G107-1 -> -0.028921328

Sheet Market Return
B2: Return on Markets
B4: Year | C4: Annual | E4: Average Return | G4: =AVERAGE(C4:C26) -> 0.15949091
B5: 2000 | C5: -0.1465 | E5: Dividend Yield 1 | G5: 0.0128
B6: 2001 | C6: -0.1618 | E6: Total Market Returns | G6: =SUM(G4:G5) -> 0.17229091
B7: 2002 | C7: 0.0325
B8: 2003 | C8: 0.719
B9: 2004 | C9: 0.1068
B10: 2005 | C10: 0.3634
B11: 2006 | C11: 0.3983
B12: 2007 | C12: 0.5477
B13: 2008 | C13: -0.5179
B14: 2009 | C14: 0.7576
B15: 2010 | C15: 0.1795
B16: 2011 | C16: -0.2462
B17: 2012 | C17: 0.277
B18: 2013 | C18: 0.0676
... B30: 2025 | C30: 0.1051

Sheet Intrinsic Growth
B2: Calculation of ROIC | D2: ='Historical FS'!H3 -> 44286 | E2: ='Historical FS'!I3 -> 44651 | F2: ='Historical FS'!J3 -> 45016 | G2: ='Historical FS'!K3 -> 45382 | H2: ='Historical FS'!L3 -> 45747
B4: Current Assets
B5: Inventories | D5: 0 | E5: 0 | F5: 0 | G5: 0 | H5: 0
B6: Trade receivables | D6: ='Raw FS'!J33 -> 19294 | E6: ='Raw FS'!K33 -> 22698 | F6: ='Raw FS'!L33 -> 25424 | G6: ='Raw FS'!M33 -> 30193 | H6: ='Raw FS'!N33 -> 31158
B7: Loans n Advances | D7: ='Raw FS'!J35 -> 1460 | E7: ='Raw FS'!K35 -> 2491 | F7: ='Raw FS'!L35 -> 3242 | G7: ='Raw FS'!M35 -> 10330 | H7: ='Raw FS'!N35 -> 6717
B8: Other asset items | D8: ='Raw FS'!J36 -> 21411 | E8: ='Raw FS'!K36 -> 27528 | F8: ='Raw FS'!L36 -> 34766 | G8: ='Raw FS'!M36 -> 29513 | H8: ='Raw FS'!N36 -> 30149
B9: Total Current Assets | D9: =SUM(D6:D8) -> 42165 | E9: =SUM(E6:E8) -> 52717 | F9: =SUM(F6:F8) -> 63432 | G9: =SUM(G6:G8) -> 70036 | H9: =SUM(H6:H8) -> 68024
B11: Current Liabilities
B12: Trade Payables | D12: ='Raw FS'!J10 -> 2645 | E12: ='Raw FS'!K10 -> 4134 | F12: ='Raw FS'!L10 -> 3865 | G12: ='Raw FS'!M10 -> 3956 | H12: ='Raw FS'!N10 -> 4164
B13: Advance from Customers | D13: ='Raw FS'!J11 -> 0 | E13: ='Raw FS'!K11 -> 0 | F13: ='Raw FS'!L11 -> 0 | G13: ='Raw FS'!M11 -> 0 | H13: ='Raw FS'!N11 -> 0
B14: Other liability items | D14: ='Raw FS'!J12 -> 22759 | E14: ='Raw FS'!K12 -> 31385 | F14: ='Raw FS'!L12 -> 36637 | G14: ='Raw FS'!M12 -> 36584 | H14: ='Raw FS'!N12 -> 39201
B15: Total Current Liabilities | D15: =SUM(D12:D14) -> 25404 | E15: =SUM(E12:E14) -> 35519 | F15: =SUM(F12:F14) -> 40502 | G15: =SUM(G12:G14) -> 40540 | H15: =SUM(H12:H14) -> 43365
B17: Net Working Capital | D17: =D9-D15 -> 16761 | E17: =E9-E15 -> 17198 | F17: =F9-F15 -> 22930 | G17: =G9-G15 -> 29496 | H17: =H9-H15 -> 24659
B19: Non Current Assets
B20: Land | D20: ='Raw FS'!J16 -> 2036 | E20: ='Raw FS'!K16 -> 2065 | F20: ='Raw FS'!L16 -> 2054 | G20: ='Raw FS'!M16 -> 2037 | H20: ='Raw FS'!N16 -> 2079
B21: Building | D21: ='Raw FS'!J17 -> 16328 | E21: ='Raw FS'!K17 -> 16761 | F21: ='Raw FS'!L17 -> 16903 | G21: ='Raw FS'!M17 -> 16515 | H21: ='Raw FS'!N17 -> 16376
B22: Plant Machinery | D22: ='Raw FS'!J18 -> 3296 | E22: ='Raw FS'!K18 -> 3210 | F22: ='Raw FS'!L18 -> 3302 | G22: ='Raw FS'!M18 -> 3428 | H22: ='Raw FS'!N18 -> 3461
B23: Equipments | D23: ='Raw FS'!J19 -> 1371 | E23: ='Raw FS'!K19 -> 1427 | F23: ='Raw FS'!L19 -> 1482 | G23: ='Raw FS'!M19 -> 1528 | H23: ='Raw FS'!N19 -> 1628
B24: Computer | D24: ='Raw FS'!J20 -> 8650 | E24: ='Raw FS'!K20 -> 9936 | F24: ='Raw FS'!L20 -> 11898 | G24: ='Raw FS'!M20 -> 12353 | H24: ='Raw FS'!N20 -> 12925
B25: Furniture n fittings | D25: ='Raw FS'!J21 -> 2149 | E25: ='Raw FS'!K21 -> 2279 | F25: ='Raw FS'!L21 -> 2303 | G25: ='Raw FS'!M21 -> 2326 | H25: ='Raw FS'!N21 -> 2340
B26: Vehicles | D26: ='Raw FS'!J22 -> 74 | E26: ='Raw FS'!K22 -> 71 | F26: ='Raw FS'!L22 -> 60 | G26: ='Raw FS'!M22 -> 62 | H26: ='Raw FS'!N22 -> 72
B27: Intangible Assets | D27: ='Raw FS'!J23 -> 6372 | E27: ='Raw FS'!K23 -> 6495 | F27: ='Raw FS'!L23 -> 7594 | G27: ='Raw FS'!M23 -> 7653 | H27: ='Raw FS'!N23 -> 10626
B28: Other fixed assets | D28: ='Raw FS'!J24 -> 2730 | E28: ='Raw FS'!K24 -> 2766 | F28: ='Raw FS'!L24 -> 3281 | G28: ='Raw FS'!M24 -> 3294 | H28: ='Raw FS'!N24 -> 5184
B30: Gross Block | D30: =SUM(D20:D28) -> 43006 | E30: =SUM(E20:E28) -> 45010 | F30: =SUM(F20:F28) -> 48877 | G30: =SUM(G20:G28) -> 49196 | H30: =SUM(H20:H28) -> 54691
B31: Accumulated Depreciation | D31: ='Raw FS'!J26 -> 17501 | E31: ='Raw FS'!K26 -> 19210 | F31: ='Raw FS'!L26 -> 19652 | G31: ='Raw FS'!M26 -> 21574 | H31: ='Raw FS'!N26 -> 23730
B32: Net Non Current Assets | D32: =D30-D31 -> 25505 | E32: =E30-E31 -> 25800 | F32: =F30-F31 -> 29225 | G32: =G30-G31 -> 27622 | H32: =H30-H31 -> 30961
B34: Invested Capital | D34: =D32+D17 -> 42266 | E34: =E32+E17 -> 42998 | F34: =F32+F17 -> 52155 | G34: =G32+G17 -> 57118 | H34: =H32+H17 -> 55620
B35: EBIT | D35: ='Historical FS'!H27+'Historical FS'!H21 -> 24622 | E35: ='Historical FS'!I27+'Historical FS'!I21 -> 28015 | F35: ='Historical FS'!J27+'Historical FS'!J21 -> 30905 | G35: ='Historical FS'!K27+'Historical FS'!K21 -> 31747 | H35: ='Historical FS'!L27+'Historical FS'!L21 -> 34424
B37: ROIC | D37: =D35/D34 -> 0.58254862 | E37: =E35/E34 -> 0.65154193 | F37: =F35/F34 -> 0.59256064 | G37: =G35/G34 -> 0.55581428 | H37: =H35/H34 -> 0.61891406
B40: Calculation of Reinvestment Rate | D40: =D2 -> 44286 | E40: =E2 -> 44651 | F40: =F2 -> 45016 | G40: =G2 -> 45382 | H40: =H2 -> 45747
B42: Net Capex | D42: =-SUM('Raw FS'!J49:J50) -> 2107 | E42: =-SUM('Raw FS'!K49:K50) -> 2161 | F42: =-SUM('Raw FS'!L49:L50) -> 2579 | G42: =-SUM('Raw FS'!M49:M50) -> 2201 | H42: =-SUM('Raw FS'!N49:N50) -> 2237
B43: Change in Working Capital | E43: =E17-D17 -> 437 | F43: =F17-E17 -> 5732 | G43: =G17-F17 -> 6566 | H43: =H17-G17 -> -4837
B45: EBIT | D45: =D35 -> 24622 | E45: =E35 -> 28015 | F45: =F35 -> 30905 | G45: =G35 -> 31747 | H45: =H35 -> 34424
B46: Marginal Tax Rate | D46: 0.25 | E46: 0.25 | F46: 0.25 | G46: 0.25 | H46: 0.25
B47: EBIT(1-T) | D47: =D45*(1-D46) -> 18466.5 | E47: =E45*(1-E46) -> 21011.25 | F47: =F45*(1-F46) -> 23178.75 | G47: =G45*(1-G46) -> 23810.25 | H47: =H45*(1-H46) -> 25818
B49: Reinvestment | E49: =SUM(E42:E43) -> 2598 | F49: =SUM(F42:F43) -> 8311 | G49: =SUM(G42:G43) -> 8767 | H49: =SUM(H42:H43) -> -2600
B51: Reinvestment Rate | E51: =E49/E47 -> 0.12364805 | F51: =F49/F47 -> 0.35856118 | G51: =G49/G47 -> 0.36820277 | H51: =H49/H47 -> -0.10070493
G53: 4 Year Average | H53: =AVERAGE(E51:H51) -> 0.18742677
G54: 4 Year Median | H54: =MEDIAN(E51:H51) -> 0.24110461
B56: Calculation of Growth Rate | D56: =D40 -> 44286 | E56: =E40 -> 44651 | F56: =F40 -> 45016 | G56: =G40 -> 45382 | H56: =H40 -> 45747
...

Sheet DCF
B2: Calculation of PV of FCFF | F2: ='Historical FS'!L3 -> 45747 | G2: =F2+365 -> 46112 | H2: =G2+365 -> 46477 | I2: =H2+365 -> 46842 | J2: =I2+365 -> 47207 | K2: =J2+365 -> 47572
B4: EBIT | F4: ='Data Sheet'!K33-'Data Sheet'!K26 -> 37987 | G4: =F4*(1+$C$14) -> 43404.217 | H4: =G4*(1+$C$14) -> 49593.967 | I4: =H4*(1+$C$14) -> 56666.42 | J4: =I4*(1+$C$14) -> 64747.455 | K4: =J4*(1+$C$14) -> 73980.903
B5: Tax Rate | F5: 0.25 | G5: 0.25 | H5: 0.25 | I5: 0.25 | J5: 0.25 | K5: 0.25
B6: EBIT(1-T) | F6: =F4*(1-F5) -> 28490.25 | G6: =G4*(1-G5) -> 32553.163 | H6: =H4*(1-H5) -> 37195.475 | I6: =I4*(1-I5) -> 42499.815 | J6: =J4*(1-J5) -> 48560.591 | K6: =K4*(1-K5) -> 55485.678
B7: Less: Reinvestment Rate | F7: ='Intrinsic Growth'!H54 -> 0.24110461 | G7: =F7+(($K$7-$F$7)/4) -> 0.24332846 | H7: =G7+(($K$7-$F$7)/4) -> 0.24555231 | I7: =H7+(($K$7-$F$7)/4) -> 0.24777615 | J7: =I7+(($K$7-$F$7)/4) -> 0.25 | K7: 0.25
B8: Free Cash Flow to Firm (FCFF) | F8: =F6*(1-F7) -> 21621.119 | G8: =G6*(1-G7) -> 24632.052 | H8: =H6*(1-H7) -> 28062.041 | I8: =I6*(1-I7) -> 31969.374 | J8: =J6*(1-J7) -> 36420.444 | K8: =K6*(1-K7) -> 41614.258
B9: Mid Year Convention | G9: 0.5 | H9: =G9+1 -> 1.5 | I9: =H9+1 -> 2.5 | J9: =I9+1 -> 3.5 | K9: =J9+1 -> 4.5
B10: Discounting Factor | G10: =1/(1+$C$16)^G9 -> 0.9316544 | H10: =1/(1+$C$16)^H9 -> 0.8086573 | I10: =1/(1+$C$16)^I9 -> 0.70189829 | J10: =1/(1+$C$16)^J9 -> 0.60923362 | K10: =1/(1+$C$16)^K9 -> 0.52880254
B12: PV of FCFF | G12: =G8*G10 -> 22948.559 | H12: =H8*H10 -> 22692.574 | I12: =I8*I10 -> 22439.249 | J12: =J8*J10 -> 22188.559 | K12: =K8*K10 -> 22005.726
B14: Expected Growth | C14: ='Intrinsic Growth'!H64 -> 0.14260712
B15: Terminal Growth | C15: 0.074 | E15: Sensitivity Analysis
B16: WACC | C16: =WACC!J40 -> 0.1521004 | G16: WACC
F17: =C37 -> 1110.7337 | G17: 0.13 | H17: 0.1521 | I17: 0.17 | J17: 0.19
B18: Calculation of Terminal Value | E18: Growth Rate | F18: 0.05 | G18: 1091.8833 | H18: 924.12798 | I18: 833.54515 | J18: 759.73423
F19: 0.06 | G19: 1202.5997 | H19: 990.06275 | I19: 880.51573 | J19: 793.80081
B20: FCFF (n+1) | C20: =K8*(1+C14) -> 47548.748 | F20: 0.074 | G20: 1424.0325 | H20: 1110.7377 | I20: 962.71425 | J20: 851.36157
B21: WACC | C21: =C16 -> 0.1521004 | F21: 0.08 | G21: 1556.8921 | H21: 1176.8017 | I21: 1005.7706 | J21: 880.51573
B22: Terminal Growth Rate | C22: =C15 -> 0.074 | F22: 0.09 | G22: 1866.898 | H22: 1315.2773 | I22: 1091.8833 | J22: 936.88043
B24: Terminal Value | C24: =C20/(C21-C22) -> 608815.71 | E24: Sensitivity Analysis
G25: WACC
B26: Calculation of Equity Value Per Share | F26: =C24 -> 608815.71 | G26: 0.13 | H26: 0.1521 | I26: 0.17 | J26: 0.19
E27: Growth Rate | F27: 0.05 | G27: 594359.35 | H27: 465707.62 | I27: 396239.56 | J27: 339633.91
B28: PV of FCFF | C28: =SUM(G12:K12) -> 112274.67 | F28: 0.06 | G28: 679267.82 | H28: 516273.05 | I28: 432261.34 | J28: 365759.6
B29: PV of Terminal Value | C29: =C24*K10 -> 321943.3 | F29: 0.074 | G29: 849084.78 | H29: 608818.79 | I29: 495299.46 | J29: 409903
B30: Value of Opreating Assets | C30: =SUM(C28:C29) -> 434217.96 | F30: 0.08 | G30: 950974.95 | H30: 659483.33 | I30: 528319.42 | J30: 432261.34
F31: 0.09 | G31: 1188718.7 | H31: 765680.32 | I31: 594359.35 | J31: 475487.48
B32: Add: Cash | C32: ='Data Sheet'!K69 -> 24455
B33: Less: Debt | C33: ='Raw FS'!N7 -> 8227
B34: Value of Equity | C34: =C30+C32-C33 -> 450445.96
B35: No of Shares | C35: ='Data Sheet'!B6 -> 405.53911
N36: 0.09
B37: Equity Value Per Share | C37: =C34/C35 -> 1110.7337
B39: Share Price | C39: 1315
B40: Discount/Premium | C40: =C39/C37 -> 1.1839021

Sheet Dupont nalysis
B3: ='Data Sheet'!B1 -> INFOSYS LTD
B4: (INFY | BSE Code 500209)
B5: 1262.4
B6: 52 week (High - 1,728.00 INR & Low - 1,258.00)
B8: About the Company
B14: Financial Summary
B58: Dupont Analysis - Return on Equity & Return on Assets
B60: Return on Equity (ROE)
C61: ='Historical FS'!F3 -> 43555 | D61: ='Historical FS'!G3 -> 43921 | E61: ='Historical FS'!H3 -> 44286 | F61: ='Historical FS'!I3 -> 44651 | G61: ='Historical FS'!J3 -> 45016 | H61: ='Historical FS'!K3 -> 45382 | I61: ='Historical FS'!L3 -> 45747
B62: Net Profit | C62: ='Data Sheet'!E30 -> 15404 | D62: ='Data Sheet'!F30 -> 16594 | E62: ='Data Sheet'!G30 -> 19351 | F62: ='Data Sheet'!H30 -> 22110 | G62: ='Data Sheet'!I30 -> 24095 | H62: ='Data Sheet'!J30 -> 26233 | I62: ='Data Sheet'!K30 -> 26713
B63: Average shareholder Equity | C63: =(('Data Sheet'!E57+'Data Sheet'!E58)+('Data Sheet'!D57+'Data Sheet'!D58))/2 -> 64935.5 | D63: =(('Data Sheet'!F57+'Data Sheet'!F58)+('Data Sheet'!E57+'Data Sheet'!E58))/2 -> 65199 | E63: =(('Data Sheet'!G57+'Data Sheet'!G58)+('Data Sheet'!F57+'Data Sheet'!F58))/2 -> 70900.5 | F63: =(('Data Sheet'!H57+'Data Sheet'!H58)+('Data Sheet'!G57+'Data Sheet'!G58))/2 -> 75850.5 | G63: =(('Data Sheet'!I57+'Data Sheet'!I58)+('Data Sheet'!H57+'Data Sheet'!H58))/2 -> 75378.5 | H63: =(('Data Sheet'!J57+'Data Sheet'!J58)+('Data Sheet'!I57+'Data Sheet'!I58))/2 -> 81761.5 | I63: =(('Data Sheet'!K57+'Data Sheet'!K58)+('Data Sheet'!J57+'Data Sheet'!J58))/2 -> 91967
B64: Return on Equity (ROE) | C64: =C62/C63 -> 0.23722001 | D64: =D62/D63 -> 0.25451311 | E64: =E62/E63 -> 0.27293178 | F64: =F62/F63 -> 0.29149445 | G64: =G62/G63 -> 0.31965348 | H64: =H62/H63 -> 0.32084783 | I64: =I62/I63 -> 0.29046288
B66: Return on Equity (ROE) - Dupont Equiation
C67: =C61 -> 43555 | D67: =D61 -> 43921 | E67: =E61 -> 44286 | F67: =F61 -> 44651 | G67: =G61 -> 45016 | H67: =H61 -> 45382 | I67: =I61 -> 45747
B68: Net Profit | C68: =C62 -> 15404 | D68: =D62 -> 16594 | E68: =E62 -> 19351 | F68: =F62 -> 22110 | G68: =G62 -> 24095 | H68: =H62 -> 26233 | I68: =I62 -> 26713
B69: Revenue | C69: ='Data Sheet'!E17 -> 82675 | D69: ='Data Sheet'!F17 -> 90791 | E69: ='Data Sheet'!G17 -> 100472 | F69: ='Data Sheet'!H17 -> 121641 | G69: ='Data Sheet'!I17 -> 146767 | H69: ='Data Sheet'!J17 -> 153670 | I69: ='Data Sheet'!K17 -> 162990
B70: Net Profit Margin (A) | C70: =C68/C69 -> 0.18631993 | D70: =D68/D69 -> 0.18277142 | E70: =E68/E69 -> 0.19260092 | F70: =F68/F69 -> 0.18176437 | G70: =G68/G69 -> 0.16417178 | H70: =H68/H69 -> 0.17070996 | I70: =I68/I69 -> 0.16389349
B72: Revenue | C72: =C69 -> 82675 | D72: =D69 -> 90791 | E72: =E69 -> 100472 | F72: =F69 -> 121641 | G72: =G69 -> 146767 | H72: =H69 -> 153670 | I72: =I69 -> 162990
B73: Average Total Assets | C73: =('Data Sheet'!E66+'Data Sheet'!D66)/2 -> 81707.5 | D73: =('Data Sheet'!F66+'Data Sheet'!E66)/2 -> 87933 | E73: =('Data Sheet'!G66+'Data Sheet'!F66)/2 -> 99655.5 | F73: =('Data Sheet'!H66+'Data Sheet'!G66)/2 -> 112120 | G73: =('Data Sheet'!I66+'Data Sheet'!H66)/2 -> 120662.5 | H73: =('Data Sheet'!J66+'Data Sheet'!I66)/2 -> 130978 | I73: =('Data Sheet'!K66+'Data Sheet'!J66)/2 -> 142577.5
B74: Asset Turnover Ratio (B) | C74: =C72/C73 -> 1.011841 | D74: =D72/D73 -> 1.032502 | E74: =E72/E73 -> 1.0081932 | F74: =F72/F73 -> 1.0849179 | G74: =G72/G73 -> 1.2163431 | H74: =H72/H73 -> 1.1732505 | I74: =I72/I73 -> 1.1431678
B76: =B95 -> Average Total Assets | C76: =C95 -> 81707.5 | D76: =D95 -> 87933 | E76: =E95 -> 99655.5 | F76: =F95 -> 112120 | G76: =G95 -> 120662.5 | H76: =H95 -> 130978 | I76: =I95 -> 142577.5
B77: =B63 -> Average shareholder Equity | C77: =C63 -> 64935.5 | D77: =D63 -> 65199 | E77: =E63 -> 70900.5 | F77: =F63 -> 75850.5 | G77: =G63 -> 75378.5 | H77: =H63 -> 81761.5 | I77: =I63 -> 91967
B78: Equity Multiplier (c) | C78: =C76/C77 -> 1.2582871 | D78: =D76/D77 -> 1.3486863 | E78: =E76/E77 -> 1.4055684 | F78: =F76/F77 -> 1.4781709 | G78: =G76/G77 -> 1.6007549 | H78: =H76/H77 -> 1.601952 | I78: =I76/I77 -> 1.5503115
B80: Return on Equity (A*B*C) | C80: =C78*C96*C92 -> 0.23722001 | D80: =D78*D96*D92 -> 0.25451311 | E80: =E78*E96*E92 -> 0.27293178 | F80: =F78*F96*F92 -> 0.29149445 | G80: =G78*G96*G92 -> 0.31965348 | H80: =H78*H96*H92 -> 0.32084783 | I80: =I78*I96*I92 -> 0.29046288
B82: Return on Assets
C83: =C61 -> 43555 | D83: =D61 -> 43921 | E83: =E61 -> 44286 | F83: =F61 -> 44651 | G83: =G61 -> 45016 | H83: =H61 -> 45382 | I83: =I61 -> 45747
B84: Net Profit | C84: =C62 -> 15404 | D84: =D62 -> 16594 | E84: =E62 -> 19351 | F84: =F62 -> 22110 | G84: =G62 -> 24095 | H84: =H62 -> 26233 | I84: =I62 -> 26713
B85: =B95 -> Average Total Assets | C85: =('Data Sheet'!E66+'Data Sheet'!D66)/2 -> 81707.5 | D85: =('Data Sheet'!F66+'Data Sheet'!E66)/2 -> 87933 | E85: =('Data Sheet'!G66+'Data Sheet'!F66)/2 -> 99655.5 | F85: =('Data Sheet'!H66+'Data Sheet'!G66)/2 -> 112120 | G85: =('Data Sheet'!I66+'Data Sheet'!H66)/2 -> 120662.5 | H85: =('Data Sheet'!J66+'Data Sheet'!I66)/2 -> 130978 | I85: =('Data Sheet'!K66+'Data Sheet'!J66)/2 -> 142577.5
B86: Return on Assets | C86: =C84/C85 -> 0.18852615 | D86: =D84/D85 -> 0.18871186 | E86: =E84/E85 -> 0.19417895 | F86: =F84/F85 -> 0.19719943 | G86: =G84/G85 -> 0.19968922 | H86: =H84/H85 -> 0.20028554 | I86: =I84/I85 -> 0.18735775
B88: Return on Assets (ROA) - Dupont Equiation
C89: =C61 -> 43555 | D89: =D61 -> 43921 | E89: =E61 -> 44286 | F89: =F61 -> 44651 | G89: =G61 -> 45016 | H89: =H61 -> 45382 | I89: =I61 -> 45747
B90: Net Profit | C90: =C62 -> 15404 | D90: =D62 -> 16594 | E90: =E62 -> 19351 | F90: =F62 -> 22110 | G90: =G62 -> 24095 | H90: =H62 -> 26233 | I90: =I62 -> 26713
B91: Revenue | C91: =C72 -> 82675 | D91: =D72 -> 90791 | E91: =E72 -> 100472 | F91: =F72 -> 121641 | G91: =G72 -> 146767 | H91: =H72 -> 153670 | I91: =I72 -> 162990
B92: Net Profit Margin (A) | C92: =C90/C91 -> 0.18631993 | D92: =D90/D91 -> 0.18277142 | E92: =E90/E91 -> 0.19260092 | F92: =F90/F91 -> 0.18176437 | G92: =G90/G91 -> 0.16417178 | H92: =H90/H91 -> 0.17070996 | I92: =I90/I91 -> 0.16389349
B94: Revenue | C94: =C91 -> 82675 | D94: =D91 -> 90791 | E94: =E91 -> 100472 | F94: =F91 -> 121641 | G94: =G91 -> 146767 | H94: =H91 -> 153670 | I94: =I91 -> 162990
B95: Average Total Assets | C95: =C85 -> 81707.5 | D95: =D85 -> 87933 | E95: =E85 -> 99655.5 | F95: =F85 -> 112120 | G95: =G85 -> 120662.5 | H95: =H85 -> 130978 | I95: =I85 -> 142577.5
B96: Asset Turnover Ratio (B) | C96: =C94/C95 -> 1.011841 | D96: =D94/D95 -> 1.032502 | E96: =E94/E95 -> 1.0081932 | F96: =F94/F95 -> 1.0849179 | G96: =G94/G95 -> 1.2163431 | H96: =H94/H95 -> 1.1732505 | I96: =I94/I95 -> 1.1431678
B98: Return of Assets (A)*(B) | C98: =C92*C96 -> 0.18852615 | D98: =D92*D96 -> 0.18871186 | E98: =E92*E96 -> 0.19417895 | F98: =F92*F96 -> 0.19719943 | G98: =G92*G96 -> 0.19968922 | H98: =H92*H96 -> 0.20028554 | I98: =I92*I96 -> 0.18735775

Sheet Altman's Z Score
B3: INFOSYS LTD.
B4: (INFY | BSE Code 500209)
B5: 1262.4
B6: 52 week (High - 1,728.00 INR & Low - 1,258.00)
B8: Altman's Z Score Analysis
B9: Infosys Limited is a leading global provider of information technology services and consulting, headquartered in Bengaluru. Founded in 1981 by N. R. Narayana Murthy, the company offers services such as software development, digital transformation, cloud computing, and artificial intelligence solutions.
B13: Financial Summary
B52: Altman's Z Score Analysis Calculation
B54: Working Capital / Total Assets
C55: ='Data Sheet'!E56 -> 43555 | D55: ='Data Sheet'!F56 -> 43921 | E55: ='Data Sheet'!G56 -> 44286 | F55: ='Data Sheet'!H56 -> 44651 | G55: ='Data Sheet'!I56 -> 45016 | H55: ='Data Sheet'!J56 -> 45382 | I55: ='Data Sheet'!K56 -> 45747
B56: Working Capital | C56: ='Data Sheet'!E65-'Data Sheet'!E60 -> 36589 | D56: ='Data Sheet'!F65-'Data Sheet'!F60 -> 36548 | E56: ='Data Sheet'!G65-'Data Sheet'!G60 -> 41044 | F56: ='Data Sheet'!H65-'Data Sheet'!H60 -> 34284 | G56: ='Data Sheet'!I65-'Data Sheet'!I60 -> 34715 | H56: ='Data Sheet'!J65-'Data Sheet'!J60 -> 43937 | I56: ='Data Sheet'!K65-'Data Sheet'!K60 -> 48729
B57: Total Assets | C57: ='Data Sheet'!E66 -> 84066 | D57: ='Data Sheet'!F66 -> 91800 | E57: ='Data Sheet'!G66 -> 107511 | F57: ='Data Sheet'!H66 -> 116729 | G57: ='Data Sheet'!I66 -> 124596 | H57: ='Data Sheet'!J66 -> 137360 | I57: ='Data Sheet'!K66 -> 147795
B58: Working Capital / Total Assets (A) | C58: =C56/C57 -> 0.43524136 | D58: =D56/D57 -> 0.39812636 | E58: =E56/E57 -> 0.38176559 | F58: =F56/F57 -> 0.29370593 | G58: =G56/G57 -> 0.2786205 | H58: =H56/H57 -> 0.3198675 | I58: =I56/I57 -> 0.32970669
B60: Retained Earnings / Total Assets
C61: =C55 -> 43555 | D61: =D55 -> 43921 | E61: =E55 -> 44286 | F61: =F55 -> 44651 | G61: =G55 -> 45016 | H61: =H55 -> 45382 | I61: =I55 -> 45747
B62: Retained Earnings | C62: ='Historical FS'!F36*'Historical FS'!F38*'Historical FS'!F44 -> 3305.5 | D62: ='Historical FS'!G36*'Historical FS'!G38*'Historical FS'!G44 -> 6409 | E62: ='Historical FS'!H36*'Historical FS'!H38*'Historical FS'!H44 -> 5752.4 | F62: ='Historical FS'!I36*'Historical FS'!I38*'Historical FS'!I44 -> 6843.4 | G62: ='Historical FS'!J36*'Historical FS'!J38*'Historical FS'!J44 -> 7337.8 | H62: ='Historical FS'!K36*'Historical FS'!K38*'Historical FS'!K44 -> 2483.8 | I62: ='Historical FS'!L36*'Historical FS'!L38*'Historical FS'!L44 -> 5322.2
B63: Total Assets | C63: =C57 -> 84066 | D63: =D57 -> 91800 | E63: =E57 -> 107511 | F63: =F57 -> 116729 | G63: =G57 -> 124596 | H63: =H57 -> 137360 | I63: =I57 -> 147795
B64: Retained Earnings / Total Assets (B) | C64: =C62/C63 -> 0.039320296 | D64: =D62/D63 -> 0.069814815 | E64: =E62/E63 -> 0.053505223 | F64: =F62/F63 -> 0.058626391 | G64: =G62/G63 -> 0.058892741 | H64: =H62/H63 -> 0.018082411 | I64: =I62/I63 -> 0.03601069
B66: EBIT / Total Assets
B67: EBIT | C67: ='Historical FS'!F27+'Historical FS'!F21 -> 18159 | D67: ='Historical FS'!G27+'Historical FS'!G21 -> 19374 | E67: ='Historical FS'!H27+'Historical FS'!H21 -> 24622 | F67: ='Historical FS'!I27+'Historical FS'!I21 -> 28015 | G67: ='Historical FS'!J27+'Historical FS'!J21 -> 30905 | H67: ='Historical FS'!K27+'Historical FS'!K21 -> 31747 | I67: ='Historical FS'!L27+'Historical FS'!L21 -> 34424
B68: Total Assets | C68: =C63 -> 84066 | D68: =D63 -> 91800 | E68: =E63 -> 107511 | F68: =F63 -> 116729 | G68: =G63 -> 124596 | H68: =H63 -> 137360 | I68: =I63 -> 147795
B69: EBIT/Total Assets (C) | C69: =C67/C68 -> 0.21600885 | D69: =D67/D68 -> 0.21104575 | E69: =E67/E68 -> 0.22901843 | F69: =F67/F68 -> 0.24000034 | G69: =G67/G68 -> 0.24804167 | H69: =H67/H68 -> 0.2311226 | I69: =I67/I68 -> 0.23291722
B71: Market Cap / Long term Liabilities
B72: Market Cap | C72: =('Data Sheet'!E90*'Data Sheet'!E70)/10000000 -> 322529.97 | D72: =('Data Sheet'!F90*'Data Sheet'!F70)/10000000 -> 272044.32 | E72: =('Data Sheet'!G90*'Data Sheet'!G70)/10000000 -> 580757.21 | F72: =('Data Sheet'!H90*'Data Sheet'!H70)/10000000 -> 799544.67 | G72: =('Data Sheet'!I90*'Data Sheet'!I70)/10000000 -> 590655.51 | H72: =('Data Sheet'!J90*'Data Sheet'!J70)/10000000 -> 620185.3 | I72: =('Data Sheet'!K90*'Data Sheet'!K70)/10000000 -> 650815.72
B73: Long term Liabilities | C73: ='Data Sheet'!E59 -> 0 | D73: ='Data Sheet'!F59 -> 4633 | E73: ='Data Sheet'!G59 -> 5325 | F73: ='Data Sheet'!H59 -> 5474 | G73: ='Data Sheet'!I59 -> 8299 | H73: ='Data Sheet'!J59 -> 8359 | I73: ='Data Sheet'!K59 -> 8227
B74: Market Cap / Long term Liabilities (D) | D74: =D72/D73 -> 58.718825 | E74: =E72/E73 -> 109.06239 | F74: =F72/F73 -> 146.06223 | G74: =G72/G73 -> 71.17189 | H74: =H72/H73 -> 74.19372 | I74: =I72/I73 -> 79.107295
B76: Sales / Total Assets
C77: =C61 -> 43555 | D77: =D61 -> 43921 | E77: =E61 -> 44286 | F77: =F61 -> 44651 | G77: =G61 -> 45016 | H77: =H61 -> 45382 | I77: =I61 -> 45747
B78: Total Sales | C78: ='Historical FS'!F6 -> 82675 | D78: ='Historical FS'!G6 -> 90791 | E78: ='Historical FS'!H6 -> 100472 | F78: ='Historical FS'!I6 -> 121641 | G78: ='Historical FS'!J6 -> 146767 | H78: ='Historical FS'!K6 -> 153670 | I78: ='Historical FS'!L6 -> 162990
B79: Total Assets | C79: =C63 -> 84066 | D79: =D63 -> 91800 | E79: =E63 -> 107511 | F79: =F63 -> 116729 | G79: =G63 -> 124596 | H79: =H63 -> 137360 | I79: =I63 -> 147795
B80: Return on Asset (E) | C80: =C78/C79 -> 0.98345348 | D80: =D78/D79 -> 0.98900871 | E80: =E78/E79 -> 0.93452763 | F80: =F78/F79 -> 1.0420804 | G80: =G78/G79 -> 1.1779431 | H80: =H78/H79 -> 1.1187391 | I80: =I78/I79 -> 1.1028113
B82: Altman's Z Score
C83: =C77 -> 43555 | D83: =D77 -> 43921 | E83: =E77 -> 44286 | F83: =F77 -> 44651 | G83: =G77 -> 45016 | H83: =H77 -> 45382 | I83: =I77 -> 45747
B84: Final Score | C84: =(C58*1.2)+(C64*1.4)+(C69*3.3)+(C74*0.6)*(C80*1) -> 1.2901672 | D84: =(D58*1.2)+(D64*1.4)+(D69*3.3)+(D74*0.6)*(D80*1) -> 36.116001 | E84: =(E58*1.2)+(E64*1.4)+(E69*3.3)+(E74*0.6)*(E80*1) -> 62.441876 | F84: =(F58*1.2)+(F64*1.4)+(F69*3.3)+(F74*0.6)*(F80*1) -> 92.551678 | G84: =(G58*1.2)+(G64*1.4)+(G69*3.3)+(G74*0.6)*(G80*1) -> 51.537194 | H84: =(H58*1.2)+(H64*1.4)+(H69*3.3)+(H74*0.6)*(H80*1) -> 50.973909 | I84: =(I58*1.2)+(I64*1.4)+(I69*3.3)+(I74*0.6)*(I80*1) -> 53.558942
B85: Financial Stability | C85: =IF(C84<1.81," Distressed",IF(C84>3,"Strong","Grey Zone")) -> Distressed | D85: =IF(D84<1.81," Distressed",IF(D84>3,"Strong","Grey Zone")) -> Strong | E85: =IF(E84<1.81," Distressed",IF(E84>3,"Strong","Grey Zone")) -> Strong | F85: =IF(F84<1.81," Distressed",IF(F84>3,"Strong","Grey Zone")) -> Strong | G85: =IF(G84<1.81," Distressed",IF(G84>3,"Strong","Grey Zone")) -> Strong | H85: =IF(H84<1.81," Distressed",IF(H84>3,"Strong","Grey Zone")) -> Strong | I85: =IF(I84<1.81," Distressed",IF(I84>3,"Strong","Grey Zone")) -> Strong

Sheet Data Room>

Sheet Historical FS
B2: ="Historical Financial Statement - "&'[1]Data Sheet'!B1 -> Historical Financial Statement - INFOSYS LTD
B3: Years | C3: ='[1]Data Sheet'!B16 -> 42460 | D3: ='[1]Data Sheet'!C16 -> 42825 | E3: ='[1]Data Sheet'!D16 -> 43190 | F3: ='[1]Data Sheet'!E16 -> 43555 | G3: ='[1]Data Sheet'!F16 -> 43921 | H3: ='[1]Data Sheet'!G16 -> 44286 | I3: ='[1]Data Sheet'!H16 -> 44651 | J3: ='[1]Data Sheet'!I16 -> 45016 | ... L3: ='[1]Data Sheet'!K16 -> 45747 | M3: LTM
A5: # | B5: Income Statement
B6: Sales | C6: =IFERROR('[1]Data Sheet'!B17,'[1]Data Sheet'!C17) -> 62441 | D6: =IFERROR('[1]Data Sheet'!C17,'[1]Data Sheet'!D17) -> 68484 | E6: =IFERROR('[1]Data Sheet'!D17,'[1]Data Sheet'!E17) -> 70522 | F6: =IFERROR('[1]Data Sheet'!E17,'[1]Data Sheet'!F17) -> 82675 | G6: =IFERROR('[1]Data Sheet'!F17,'[1]Data Sheet'!G17) -> 90791 | H6: =IFERROR('[1]Data Sheet'!G17,'[1]Data Sheet'!H17) -> 100472 | I6: =IFERROR('[1]Data Sheet'!H17,'[1]Data Sheet'!I17) -> 121641 | J6: =IFERROR('[1]Data Sheet'!I17,'[1]Data Sheet'!J17) -> 146767 | ... L6: =IFERROR('[1]Data Sheet'!K17,'[1]Data Sheet'!L17) -> 162990 | M6: =IFERROR(SUM('[1]Data Sheet'!H42:K42),0) -> 173173
B7: Sales Growth | D7: =D6/C6-1 -> 0.09677936 | E7: =E6/D6-1 -> 0.029758776 | F7: =F6/E6-1 -> 0.1723292 | G7: =G6/F6-1 -> 0.098167523 | H7: =H6/G6-1 -> 0.10662951 | I7: =I6/H6-1 -> 0.21069552 | J7: =J6/I6-1 -> 0.20655864 | K7: =K6/J6-1 -> 0.047033734 | ... M7: =M6/L6-1 -> 0.062476226
B9: COGS | C9: =IFERROR(SUM('[1]Data Sheet'!B20:B22)-1*'[1]Data Sheet'!B19,0) -> 40492 | D9: =IFERROR(SUM('[1]Data Sheet'!C20:C22)-1*'[1]Data Sheet'!C19,0) -> 44609 | E9: =IFERROR(SUM('[1]Data Sheet'!D20:D22)-1*'[1]Data Sheet'!D19,0) -> 46395 | F9: =IFERROR(SUM('[1]Data Sheet'!E20:E22)-1*'[1]Data Sheet'!E19,0) -> 55446 | G9: =IFERROR(SUM('[1]Data Sheet'!F20:F22)-1*'[1]Data Sheet'!F19,0) -> 62210 | H9: =IFERROR(SUM('[1]Data Sheet'!G20:G22)-1*'[1]Data Sheet'!G19,0) -> 68490 | I9: =IFERROR(SUM('[1]Data Sheet'!H20:H22)-1*'[1]Data Sheet'!H19,0) -> 84819 | J9: =IFERROR(SUM('[1]Data Sheet'!I20:I22)-1*'[1]Data Sheet'!I19,0) -> 104880 | ... L9: =IFERROR(SUM('[1]Data Sheet'!K20:K22)-1*'[1]Data Sheet'!K19,0) -> 116585 | M9: =IFERROR(SUM('[1]Data Sheet'!H43:K43),0) -> 132187
B10: COGS % sales | C10: =C9/C6 -> 0.64848417 | D10: =D9/D6 -> 0.65137842 | E10: =E9/E6 -> 0.65787981 | F10: =F9/F6 -> 0.67065014 | G10: =G9/G6 -> 0.68520007 | H10: =H9/H6 -> 0.68168246 | I10: =I9/I6 -> 0.69728957 | J10: =J9/J6 -> 0.71460206 | ... M10: =M9/M6 -> 0.76332338
B12: Gross Profit | C12: =C6-C9 -> 21949 | D12: =D6-D9 -> 23875 | E12: =E6-E9 -> 24127 | F12: =F6-F9 -> 27229 | G12: =G6-G9 -> 28581 | H12: =H6-H9 -> 31982 | I12: =I6-I9 -> 36822 | J12: =J6-J9 -> 41887 | ... M12: =M6-M9 -> 40986
B13: Gross Margin | C13: =C12/C6 -> 0.35151583 | D13: =D12/D6 -> 0.34862158 | E13: =E12/E6 -> 0.34212019 | F13: =F12/F6 -> 0.32934986 | G13: =G12/G6 -> 0.31479993 | H13: =H12/H6 -> 0.31831754 | I13: =I12/I6 -> 0.30271043 | J13: =J12/J6 -> 0.28539794 | ... M13: =M12/M6 -> 0.23667662
B15: Selling & Admin Exp. | C15: =IFERROR(SUM('[1]Data Sheet'!B23:B24),0) -> 4870 | D15: =IFERROR(SUM('[1]Data Sheet'!C23:C24),0) -> 5271 | E15: =IFERROR(SUM('[1]Data Sheet'!D23:D24),0) -> 5305 | F15: =IFERROR(SUM('[1]Data Sheet'!E23:E24),0) -> 7059 | G15: =IFERROR(SUM('[1]Data Sheet'!F23:F24),0) -> 6314 | H15: =IFERROR(SUM('[1]Data Sheet'!G23:G24),0) -> 4093 | I15: =IFERROR(SUM('[1]Data Sheet'!H23:H24),0) -> 5331 | J15: =IFERROR(SUM('[1]Data Sheet'!I23:I24),0) -> 6757 | ... L15: =IFERROR(SUM('[1]Data Sheet'!K23:K24),0) -> 7169
B16: S & A % Sales | C16: =C15/C6 -> 0.077993626 | D16: =D15/D6 -> 0.076966883 | E16: =E15/E6 -> 0.075224753 | F16: =F15/F6 -> 0.085382522 | G16: =G15/G6 -> 0.069544338 | H16: =H15/H6 -> 0.040737718 | I16: =I15/I6 -> 0.043825684 | J16: =J15/J6 -> 0.04603896 | ... L16: =L15/L6 -> 0.043984294
B18: EBITDA | C18: =C12-C15 -> 17079 | D18: =D12-D15 -> 18604 | E18: =E12-E15 -> 18822 | F18: =F12-F15 -> 20170 | G18: =G12-G15 -> 22267 | H18: =H12-H15 -> 27889 | I18: =I12-I15 -> 31491 | J18: =J12-J15 -> 35130 | ... M18: =M12-M15 -> 40986
B19: EBITDA % Sales | C19: =C18/C6 -> 0.2735222 | D19: =D18/D6 -> 0.27165469 | E19: =E18/E6 -> 0.26689544 | F19: =F18/F6 -> 0.24396734 | G19: =G18/G6 -> 0.24525559 | H19: =H18/H6 -> 0.27757982 | I19: =I18/I6 -> 0.25888475 | J19: =J18/J6 -> 0.23935898 | ... M19: =M18/M6 -> 0.23667662
B21: Interest | C21: =IFERROR(SUM('[1]Data Sheet'!B27),0) -> 0 | D21: =IFERROR(SUM('[1]Data Sheet'!C27),0) -> 0 | E21: =IFERROR(SUM('[1]Data Sheet'!D27),0) -> 0 | F21: =IFERROR(SUM('[1]Data Sheet'!E27),0) -> 0 | G21: =IFERROR(SUM('[1]Data Sheet'!F27),0) -> 170 | H21: =IFERROR(SUM('[1]Data Sheet'!G27),0) -> 195 | I21: =IFERROR(SUM('[1]Data Sheet'!H27),0) -> 200 | J21: =IFERROR(SUM('[1]Data Sheet'!I27),0) -> 284 | ... L21: =IFERROR(SUM('[1]Data Sheet'!K27),0) -> 416 | M21: =IFERROR(SUM('[1]Data Sheet'!H46:K46),) -> 413
B22: Interest % Sales | C22: =C21/C6 -> 0 | D22: =D21/D6 -> 0 | E22: =E21/E6 -> 0 | F22: =F21/F6 -> 0 | G22: =G21/G6 -> 0.0018724323 | H22: =H21/H6 -> 0.0019408392 | I22: =I21/I6 -> 0.0016441825 | J22: =J21/J6 -> 0.0019350399 | ... M22: =M21/M6 -> 0.0023848983
B24: Depreciation | C24: =IFERROR(SUM('[1]Data Sheet'!B26),0) -> 1459 | D24: =IFERROR(SUM('[1]Data Sheet'!C26),0) -> 1703 | E24: =IFERROR(SUM('[1]Data Sheet'!D26),0) -> 1863 | F24: =IFERROR(SUM('[1]Data Sheet'!E26),0) -> 2011 | G24: =IFERROR(SUM('[1]Data Sheet'!F26),0) -> 2893 | H24: =IFERROR(SUM('[1]Data Sheet'!G26),0) -> 3267 | I24: =IFERROR(SUM('[1]Data Sheet'!H26),0) -> 3476 | J24: =IFERROR(SUM('[1]Data Sheet'!I26),0) -> 4225 | ... L24: =IFERROR(SUM('[1]Data Sheet'!K26),0) -> 4812 | M24: =IFERROR(SUM('[1]Data Sheet'!H45:K45),0) -> 4776
B25: Depreciation % Sales | C25: =C24/C6 -> 0.023366058 | D25: =D24/D6 -> 0.024867122 | E25: =E24/E6 -> 0.026417288 | F25: =F24/F6 -> 0.024324161 | G25: =G24/G6 -> 0.031864392 | H25: =H24/H6 -> 0.032516522 | I25: =I24/I6 -> 0.028575891 | J25: =J24/J6 -> 0.028787125 | ... M25: =M24/M6 -> 0.027579357
B27: Earning Before Tax | C27: =IFERROR(C18-SUM(C24,C21),0) -> 15620 | D27: =IFERROR(D18-SUM(D24,D21),0) -> 16901 | E27: =IFERROR(E18-SUM(E24,E21),0) -> 16959 | F27: =IFERROR(F18-SUM(F24,F21),0) -> 18159 | G27: =IFERROR(G18-SUM(G24,G21),0) -> 19204 | H27: =IFERROR(H18-SUM(H24,H21),0) -> 24427 | I27: =IFERROR(I18-SUM(I24,I21),0) -> 27815 | J27: =IFERROR(J18-SUM(J24,J21),0) -> 30621 | ... L27: =IFERROR(L18-SUM(L24,L21),0) -> 34008 | M27: =IFERROR(SUM('[1]Data Sheet'!H47:K47),0) -> 38861
B28: EBT % Sales | C28: =C27/C6 -> 0.25015615 | D28: =D27/D6 -> 0.24678757 | E28: =E27/E6 -> 0.24047815 | F28: =F27/F6 -> 0.21964318 | G28: =G27/G6 -> 0.21151876 | H28: =H27/H6 -> 0.24312246 | I28: =I27/I6 -> 0.22866468 | J28: =J27/J6 -> 0.20863682 | ... M28: =M27/M6 -> 0.22440565
B30: Tax | C30: =IFERROR(SUM('[1]Data Sheet'!B29),0) -> 5251 | D30: =IFERROR(SUM('[1]Data Sheet'!C29),0) -> 5598 | E30: =IFERROR(SUM('[1]Data Sheet'!D29),0) -> 4241 | F30: =IFERROR(SUM('[1]Data Sheet'!E29),0) -> 5631 | G30: =IFERROR(SUM('[1]Data Sheet'!F29),0) -> 5368 | H30: =IFERROR(SUM('[1]Data Sheet'!G29),0) -> 7205 | I30: =IFERROR(SUM('[1]Data Sheet'!H29),0) -> 7964 | J30: =IFERROR(SUM('[1]Data Sheet'!I29),0) -> 9214 | ... L30: =IFERROR(SUM('[1]Data Sheet'!K29),0) -> 10858 | M30: =IFERROR(SUM('[1]Data Sheet'!H48:K48),0) -> 10858
B31: Effective Tax Rate | C31: =C30/C27 -> 0.33617157 | D31: =D30/D27 -> 0.331223 | E31: =E30/E27 -> 0.25007371 | F31: =F30/F27 -> 0.31009417 | G31: =G30/G27 -> 0.2795251 | H31: =H30/H27 -> 0.29496049 | I31: =I30/I27 -> 0.28632033 | J31: =J30/J27 -> 0.30090461 | ... M31: =M30/M27 -> 0.27940609
B33: Net Profit | C33: =(C27-C30) -> 10369 | D33: =(D27-D30) -> 11303 | E33: =(E27-E30) -> 12718 | F33: =(F27-F30) -> 12528 | G33: =(G27-G30) -> 13836 | H33: =(H27-H30) -> 17222 | I33: =(I27-I30) -> 19851 | J33: =(J27-J30) -> 21407 | ... M33: =(M27-M30) -> 28003
B34: Net Margin | C34: =C33/C6 -> 0.16606076 | D34: =D33/D6 -> 0.16504585 | E34: =E33/E6 -> 0.18034089 | F34: =F33/F6 -> 0.15153311 | G34: =G33/G6 -> 0.15239396 | H34: =H33/H6 -> 0.17141094 | I34: =I33/I6 -> 0.16319333 | J34: =J33/J6 -> 0.14585704 | ... M34: =M33/M6 -> 0.16170535
B36: No. of Shares | C36: =IFERROR('[1]Data Sheet'!B93,0) -> 459.39 | D36: =IFERROR('[1]Data Sheet'!C93,0) -> 459.39 | E36: =IFERROR('[1]Data Sheet'!D93,0) -> 436.82 | F36: =IFERROR('[1]Data Sheet'!E93,0) -> 436.89 | G36: =IFERROR('[1]Data Sheet'!F93,0) -> 425.9 | H36: =IFERROR('[1]Data Sheet'!G93,0) -> 426.07 | I36: =IFERROR('[1]Data Sheet'!H93,0) -> 420.67 | J36: =IFERROR('[1]Data Sheet'!I93,0) -> 414.86 | ... M36: =IFERROR('[1]Data Sheet'!L93,0) -> 0
B38: Earning Per Shares | C38: =C33/C36 -> 22.571236 | D38: =D33/D36 -> 24.604367 | E38: =E33/E36 -> 29.114967 | F38: =F33/F36 -> 28.67541 | G38: =G33/G36 -> 32.486499 | H38: =H33/H36 -> 40.420588 | I38: =I33/I36 -> 47.189008 | J38: =J33/J36 -> 51.60054 | ... L38: =L33/L36 -> 55.73881
B39: EPS Growth % | C39: =IFERROR(D38/C38-1,0) -> 0.090076189 | D39: =IFERROR(E38/D38-1,0) -> 0.18332521 | E39: =IFERROR(F38/E38-1,0) -> -0.015097286 | F39: =IFERROR(G38/F38-1,0) -> 0.13290442 | G39: =IFERROR(H38/G38-1,0) -> 0.24422727 | H39: =IFERROR(I38/H38-1,0) -> 0.16744981 | I39: =IFERROR(J38/I38-1,0) -> 0.093486431 | J39: =IFERROR(K38/J38-1,0) -> 0.0055153183 | ... L39: =IFERROR(M38/L38-1,0) -> -1
B41: Dividend Per Share | C41: =IFERROR('[1]Data Sheet'!B31/'[1]Historical FS'!C36,0) -> 12.077755 | D41: =IFERROR('[1]Data Sheet'!C31/'[1]Historical FS'!D36,0) -> 12.824833 | E41: =IFERROR('[1]Data Sheet'!D31/'[1]Historical FS'!E36,0) -> 21.669337 | F41: =IFERROR('[1]Data Sheet'!E31/'[1]Historical FS'!F36,0) -> 21.109433 | G41: =IFERROR('[1]Data Sheet'!F31/'[1]Historical FS'!G36,0) -> 17.438366 | H41: =IFERROR('[1]Data Sheet'!G31/'[1]Historical FS'!H36,0) -> 26.91952 | I41: =IFERROR('[1]Data Sheet'!H31/'[1]Historical FS'!I36,0) -> 30.92115 | J41: =IFERROR('[1]Data Sheet'!I31/'[1]Historical FS'!J36,0) -> 33.913127 | ... L41: =IFERROR('[1]Data Sheet'!K31/'[1]Historical FS'!L36,0) -> 42.924422
B42: Dividend Payout Ratio | C42: =IFERROR(C41/C38,0) -> 0.53509499 | D42: =IFERROR(D41/D38,0) -> 0.52124215 | E42: =IFERROR(E41/E38,0) -> 0.74426797 | F42: =IFERROR(F41/F38,0) -> 0.73615102 | G42: =IFERROR(G41/G38,0) -> 0.53678809 | H42: =IFERROR(H41/H38,0) -> 0.66598537 | I42: =IFERROR(I41/I38,0) -> 0.6552617 | J42: =IFERROR(J41/J38,0) -> 0.65722427 | ... L42: =IFERROR(L41/L38,0) -> 0.77009935
B44: Retained Earning | C44: =IFERROR(IF(C38>C41,1-C42,0),0) -> 0.46490501 | D44: =IFERROR(IF(D38>D41,1-D42,0),0) -> 0.47875785 | E44: =IFERROR(IF(E38>E41,1-E42,0),0) -> 0.25573203 | F44: =IFERROR(IF(F38>F41,1-F42,0),0) -> 0.26384898 | G44: =IFERROR(IF(G38>G41,1-G42,0),0) -> 0.46321191 | H44: =IFERROR(IF(H38>H41,1-H42,0),0) -> 0.33401463 | I44: =IFERROR(IF(I38>I41,1-I42,0),0) -> 0.3447383 | J44: =IFERROR(IF(J38>J41,1-J42,0),0) -> 0.34277573 | ... L44: =IFERROR(IF(L38>L41,1-L42,0),0) -> 0.22990065
A46: # | B46: Balance Sheet
B47: Equity Share Capital | C47: =IFERROR('[1]Data Sheet'!B57,0) -> 1144 | D47: =IFERROR('[1]Data Sheet'!C57,0) -> 1144 | E47: =IFERROR('[1]Data Sheet'!D57,0) -> 1088 | F47: =IFERROR('[1]Data Sheet'!E57,0) -> 2170 | G47: =IFERROR('[1]Data Sheet'!F57,0) -> 2122 | H47: =IFERROR('[1]Data Sheet'!G57,0) -> 2124 | I47: =IFERROR('[1]Data Sheet'!H57,0) -> 2098 | J47: =IFERROR('[1]Data Sheet'!I57,0) -> 2069 | ... L47: =IFERROR('[1]Data Sheet'!K57,0) -> 2073 | M47: =L47 -> 2073
B48: Reserves | C48: =IFERROR('[1]Data Sheet'!B58,0) -> 60600 | D48: =IFERROR('[1]Data Sheet'!C58,0) -> 67838 | E48: =IFERROR('[1]Data Sheet'!D58,0) -> 63835 | F48: =IFERROR('[1]Data Sheet'!E58,0) -> 62778 | G48: =IFERROR('[1]Data Sheet'!F58,0) -> 63328 | H48: =IFERROR('[1]Data Sheet'!G58,0) -> 74227 | I48: =IFERROR('[1]Data Sheet'!H58,0) -> 73252 | J48: =IFERROR('[1]Data Sheet'!I58,0) -> 73338 | ... L48: =IFERROR('[1]Data Sheet'!K58,0) -> 93745 | M48: =IFERROR(L48+M33,0) -> 121748
B49: Borrowings | C49: =IFERROR('[1]Data Sheet'!B59,0) -> 0 | D49: =IFERROR('[1]Data Sheet'!C59,0) -> 0 | E49: =IFERROR('[1]Data Sheet'!D59,0) -> 0 | F49: =IFERROR('[1]Data Sheet'!E59,0) -> 0 | G49: =IFERROR('[1]Data Sheet'!F59,0) -> 4633 | H49: =IFERROR('[1]Data Sheet'!G59,0) -> 5325 | I49: =IFERROR('[1]Data Sheet'!H59,0) -> 5474 | J49: =IFERROR('[1]Data Sheet'!I59,0) -> 8299 | ... L49: =IFERROR('[1]Data Sheet'!K59,0) -> 8227 | M49: =L49 -> 8227
B50: Other Liabilities | C50: =IFERROR('[1]Data Sheet'!B60,0) -> 13354 | D50: =IFERROR('[1]Data Sheet'!C60,0) -> 14166 | E50: =IFERROR('[1]Data Sheet'!D60,0) -> 14426 | F50: =IFERROR('[1]Data Sheet'!E60,0) -> 19118 | G50: =IFERROR('[1]Data Sheet'!F60,0) -> 21717 | H50: =IFERROR('[1]Data Sheet'!G60,0) -> 25835 | I50: =IFERROR('[1]Data Sheet'!H60,0) -> 35905 | J50: =IFERROR('[1]Data Sheet'!I60,0) -> 40890 | ... L50: =IFERROR('[1]Data Sheet'!K60,0) -> 43750 | M50: =IFERROR(L50*(1+M7),0) -> 46483.335
B51: Total Liability | C51: =IFERROR('[1]Data Sheet'!B61,0) -> 75098 | D51: =IFERROR('[1]Data Sheet'!C61,0) -> 83148 | E51: =IFERROR('[1]Data Sheet'!D61,0) -> 79349 | F51: =IFERROR('[1]Data Sheet'!E61,0) -> 84066 | G51: =IFERROR('[1]Data Sheet'!F61,0) -> 91800 | H51: =IFERROR('[1]Data Sheet'!G61,0) -> 107511 | I51: =IFERROR('[1]Data Sheet'!H61,0) -> 116729 | J51: =IFERROR('[1]Data Sheet'!I61,0) -> 124596 | ... L51: =IFERROR('[1]Data Sheet'!K61,0) -> 147795 | M51: =SUM(M47:M50) -> 178531.33
B53: Fixed Assets Net Block | C53: =IFERROR('[1]Data Sheet'!B62,0) -> 13386 | D53: =IFERROR('[1]Data Sheet'!C62,0) -> 14179 | E53: =IFERROR('[1]Data Sheet'!D62,0) -> 12574 | F53: =IFERROR('[1]Data Sheet'!E62,0) -> 15710 | G53: =IFERROR('[1]Data Sheet'!F62,0) -> 23789 | H53: =IFERROR('[1]Data Sheet'!G62,0) -> 25505 | I53: =IFERROR('[1]Data Sheet'!H62,0) -> 25800 | J53: =IFERROR('[1]Data Sheet'!I62,0) -> 29225 | ... L53: =IFERROR('[1]Data Sheet'!K62,0) -> 30961
B54: Capital Work in Progress | C54: =IFERROR('[1]Data Sheet'!B63,0) -> 960 | D54: =IFERROR('[1]Data Sheet'!C63,0) -> 1365 | E54: =IFERROR('[1]Data Sheet'!D63,0) -> 1606 | F54: =IFERROR('[1]Data Sheet'!E63,0) -> 1388 | G54: =IFERROR('[1]Data Sheet'!F63,0) -> 954 | H54: =IFERROR('[1]Data Sheet'!G63,0) -> 922 | I54: =IFERROR('[1]Data Sheet'!H63,0) -> 416 | J54: =IFERROR('[1]Data Sheet'!I63,0) -> 288 | ... L54: =IFERROR('[1]Data Sheet'!K63,0) -> 814
B55: Investments | C55: =IFERROR('[1]Data Sheet'!B64,0) -> 1892 | D55: =IFERROR('[1]Data Sheet'!C64,0) -> 16423 | E55: =IFERROR('[1]Data Sheet'!D64,0) -> 12163 | F55: =IFERROR('[1]Data Sheet'!E64,0) -> 11261 | G55: =IFERROR('[1]Data Sheet'!F64,0) -> 8792 | H55: =IFERROR('[1]Data Sheet'!G64,0) -> 14205 | I55: =IFERROR('[1]Data Sheet'!H64,0) -> 20324 | J55: =IFERROR('[1]Data Sheet'!I64,0) -> 19478 | ... L55: =IFERROR('[1]Data Sheet'!K64,0) -> 23541
B56: Other Assets | C56: =IFERROR('[1]Data Sheet'!B65-SUM('[1]Data Sheet'!B67:B69),0) -> 14833 | D56: =IFERROR('[1]Data Sheet'!C65-SUM('[1]Data Sheet'!C67:C69),0) -> 16234 | E56: =IFERROR('[1]Data Sheet'!D65-SUM('[1]Data Sheet'!D67:D69),0) -> 20046 | F56: =IFERROR('[1]Data Sheet'!E65-SUM('[1]Data Sheet'!E67:E69),0) -> 21312 | G56: =IFERROR('[1]Data Sheet'!F65-SUM('[1]Data Sheet'!F67:F69),0) -> 21129 | H56: =IFERROR('[1]Data Sheet'!G65-SUM('[1]Data Sheet'!G67:G69),0) -> 22871 | I56: =IFERROR('[1]Data Sheet'!H65-SUM('[1]Data Sheet'!H67:H69),0) -> 30019 | J56: =IFERROR('[1]Data Sheet'!I65-SUM('[1]Data Sheet'!I67:I69),0) -> 38008 | ... L56: =IFERROR('[1]Data Sheet'!K65-SUM('[1]Data Sheet'!K67:K69),0) -> 36866
B57: Total Non Assets | C57: =SUM(C53:C56) -> 31071 | D57: =SUM(D53:D56) -> 48201 | E57: =SUM(E53:E56) -> 46389 | F57: =SUM(F53:F56) -> 49671 | G57: =SUM(G53:G56) -> 54664 | H57: =SUM(H53:H56) -> 63503 | I57: =SUM(I53:I56) -> 76559 | J57: =SUM(J53:J56) -> 86999 | ... L57: =SUM(L53:L56) -> 92182
...

Sheet Data Sheet
A1: COMPANY NAME | B1: INFOSYS LTD | E1: =IF(B2<>B3, "A NEW VERSION OF THE WORKSHEET IS AVAILABLE", "")
A2: LATEST VERSION | B2: 2.1 | E2: PLEASE DO NOT MAKE ANY CHANGES TO THIS SHEET
A3: CURRENT VERSION | B3: 2.1
A5: META
A6: Number of shares | B6: =IF(B9>0, B9/B8, 0) -> 405.53911
A7: Face Value | B7: 5
A8: Current Price | B8: 1308.4
A9: Market Capitalization | B9: 530607.37
A15: PROFIT & LOSS
A16: Report Date | B16: 42460 | C16: 42825 | D16: 43190 | E16: 43555 | F16: 43921 | G16: 44286 | H16: 44651 | I16: 45016 | J16: 45382 | K16: 45747
A17: Sales | B17: 62441 | C17: 68484 | D17: 70522 | E17: 82675 | F17: 90791 | G17: 100472 | H17: 121641 | I17: 146767 | J17: 153670 | K17: 162990
A18: Raw Material Cost
A19: Change in Inventory
A20: Power and Fuel | B20: 217 | C20: 228 | D20: 207 | E20: 221 | F20: 229 | G20: 143 | H20: 132 | I20: 176 | J20: 199 | K20: 222
A21: Other Mfr. Exp | B21: 5860 | C21: 6712 | D21: 7286 | E21: 9902 | F21: 11086 | G21: 12800 | H21: 20690 | I21: 26330 | J21: 27195 | K21: 30395
A22: Employee Cost | B22: 34415 | C22: 37669 | D22: 38902 | E22: 45323 | F22: 50895 | G22: 55547 | H22: 63997 | I22: 78374 | J22: 82636 | K22: 85968
A23: Selling and admin | B23: 4441 | C23: 4584 | D23: 4585 | E23: 5553 | F23: 5375 | G23: 3194 | H23: 4305 | I23: 5300 | J23: 5705 | K23: 6039
A24: Other Expenses | B24: 429 | C24: 687 | D24: 720 | E24: 1506 | F24: 939 | G24: 899 | H24: 1026 | I24: 1457 | J24: 1510 | K24: 1130
A25: Other Income | B25: 3120 | C25: 3050 | D25: 3311 | E25: 2882 | F25: 2803 | G25: 2201 | H25: 2295 | I25: 2701 | J25: 4711 | K25: 3600
A26: Depreciation | B26: 1459 | C26: 1703 | D26: 1863 | E26: 2011 | F26: 2893 | G26: 3267 | H26: 3476 | I26: 4225 | J26: 4678 | K26: 4812
A27: Interest | F27: 170 | G27: 195 | H27: 200 | I27: 284 | J27: 470 | K27: 416
A28: Profit before tax | B28: 18740 | C28: 19951 | D28: 20270 | E28: 21041 | F28: 22007 | G28: 26628 | H28: 30110 | I28: 33322 | J28: 35988 | K28: 37608
A29: Tax | B29: 5251 | C29: 5598 | D29: 4241 | E29: 5631 | F29: 5368 | G29: 7205 | H29: 7964 | I29: 9214 | J29: 9740 | K29: 10858
A30: Net profit | B30: 13489 | C30: 14353 | D30: 16029 | E30: 15404 | F30: 16594 | G30: 19351 | H30: 22110 | I30: 24095 | J30: 26233 | K30: 26713
A31: Dividend Amount | B31: 5548.4 | C31: 5891.6 | D31: 9465.6 | E31: 9222.5 | F31: 7427 | G31: 11469.6 | H31: 13007.6 | I31: 14069.2 | J31: 19053.2 | K31: 17827.8
A33: EBITDA | B33: =B30+B29+B27+B26 -> 20199 | C33: =C30+C29+C27+C26 -> 21654 | D33: =D30+D29+D27+D26 -> 22133 | E33: =E30+E29+E27+E26 -> 23046 | F33: =F30+F29+F27+F26 -> 25025 | G33: =G30+G29+G27+G26 -> 30018 | H33: =H30+H29+H27+H26 -> 33750 | I33: =I30+I29+I27+I26 -> 37818 | ... K33: =K30+K29+K27+K26 -> 42799
A40: Quarters
A41: Report Date | B41: 45199 | C41: 45291 | D41: 45382 | E41: 45473 | F41: 45565 | G41: 45657 | H41: 45747 | I41: 45838 | J41: 45930 | K41: 46022
A42: Sales | B42: 38994 | C42: 38821 | D42: 37923 | E42: 39315 | F42: 40986 | G42: 41764 | H42: 40925 | I42: 42279 | J42: 44490 | K42: 45479
A43: Expenses | B43: 29554 | C43: 29684 | D43: 29139 | E43: 29878 | F43: 31177 | G43: 31649 | H43: 31051 | I43: 32336 | J43: 33955 | K43: 34845
A44: Other Income | B44: 632 | C44: 789 | D44: 2729 | E44: 838 | F44: 712 | G44: 859 | H44: 1190 | I44: 1042 | J44: 982 | K44: -150
A45: Depreciation | B45: 1166 | C45: 1176 | D45: 1163 | E45: 1149 | F45: 1160 | G45: 1203 | H45: 1299 | I45: 1140 | J45: 1182 | K45: 1155
A46: Interest | B46: 138 | C46: 131 | D46: 110 | E46: 105 | F46: 108 | G46: 101 | H46: 102 | I46: 105 | J46: 106 | K46: 100
A47: Profit before tax | B47: 8768 | C47: 8619 | D47: 10240 | E47: 9021 | F47: 9253 | G47: 9670 | H47: 9663 | I47: 9740 | J47: 10229 | K47: 9229
A48: Tax | B48: 2553 | C48: 2506 | D48: 2265 | E48: 2647 | F48: 2737 | G48: 2848 | H48: 2625 | I48: 2816 | J48: 2854 | K48: 2563
A49: Net profit | B49: 6212 | C49: 6106 | D49: 7969 | E49: 6368 | F49: 6506 | G49: 6806 | H49: 7033 | I49: 6921 | J49: 7364 | K49: 6654
A50: Operating Profit | B50: 9440 | C50: 9137 | D50: 8784 | E50: 9437 | F50: 9809 | G50: 10115 | H50: 9874 | I50: 9943 | J50: 10535 | K50: 10634
A55: BALANCE SHEET
A56: Report Date | B56: 42460 | C56: 42825 | D56: 43190 | E56: 43555 | F56: 43921 | G56: 44286 | H56: 44651 | I56: 45016 | J56: 45382 | K56: 45747
A57: Equity Share Capital | B57: 1144 | C57: 1144 | D57: 1088 | E57: 2170 | F57: 2122 | G57: 2124 | H57: 2098 | I57: 2069 | J57: 2071 | K57: 2073
...

Sheet Raw FS
B2: Particulars | C2: 41699 | D2: 42064 | E2: 42430 | F2: 42795 | G2: 43160 | H2: 43525 | I2: 43891 | J2: 44256 | K2: 44621 | L2: 44986 | M2: 45352 | N2: 45717
B4: Equity Capital | C4: 286 | D4: 572 | E4: 1144 | F4: 1144 | G4: 1088 | H4: 2170 | I4: 2122 | J4: 2124 | K4: 2098 | L4: 2069 | M4: 2071 | N4: 2073
B5: Reserves | C5: 44244 | D5: 50164 | E5: 60600 | F5: 67838 | G5: 63835 | H5: 62778 | I5: 63328 | J5: 74227 | K5: 73252 | L5: 73338 | M5: 86045 | N5: 93745
B6: Borrowings -
B7: Lease Liabilities | C7: 0 | D7: 0 | E7: 0 | F7: 0 | G7: 0 | H7: 0 | I7: 4633 | J7: 5325 | K7: 5474 | L7: 8299 | M7: 8359 | N7: 8227
B8: Other Liabilities -
B9: Non controlling int | C9: 0 | D9: 0 | E9: 0 | F9: 0 | G9: 1 | H9: 58 | I9: 394 | J9: 431 | K9: 386 | L9: 388 | M9: 345 | N9: 385
B10: Trade Payables | C10: 173 | D10: 140 | E10: 386 | F10: 367 | G10: 694 | H10: 1655 | I10: 2852 | J10: 2645 | K10: 4134 | L10: 3865 | M10: 3956 | N10: 4164
B11: Advance from Customers | C11: 40 | D11: 27 | E11: 28 | F11: 0 | G11: 0 | H11: 0 | I11: 0 | J11: 0 | K11: 0 | L11: 0 | M11: 0 | N11: 0
B12: Other liability items | C12: 12223 | D12: 15386 | E12: 12940 | F12: 13799 | G12: 13731 | H12: 17405 | I12: 18471 | J12: 22759 | K12: 31385 | L12: 36637 | M12: 36584 | N12: 39201
B13: Total Liabilities | C13: 56966 | D13: 66289 | E13: 75098 | F13: 83148 | G13: 79349 | H13: 84066 | I13: 91800 | J13: 107511 | K13: 116729 | L13: 124596 | M13: 137360 | N13: 147795
B15: Fixed Assets -
B16: Land | C16: 1142 | D16: 1564 | E16: 1622 | F16: 1095 | G16: 1229 | H16: 1307 | I16: 1950 | J16: 2036 | K16: 2065 | L16: 2054 | M16: 2037 | N16: 2079
B17: Building | C17: 5238 | D17: 6102 | E17: 6325 | F17: 8419 | G17: 9334 | H17: 10270 | I17: 15104 | J17: 16328 | K17: 16761 | L17: 16903 | M17: 16515 | N17: 16376
B18: Plant Machinery | C18: 1150 | D18: 1427 | E18: 1759 | F18: 2048 | G18: 2306 | H18: 2709 | I18: 3185 | J18: 3296 | K18: 3210 | L18: 3302 | M18: 3428 | N18: 3461
B19: Equipments | C19: 551 | D19: 676 | E19: 839 | F19: 922 | G19: 1002 | H19: 1101 | I19: 1265 | J19: 1371 | K19: 1427 | L19: 1482 | M19: 1528 | N19: 1628
B20: Computers | C20: 2659 | D20: 3347 | E20: 4486 | F20: 4945 | G20: 4903 | H20: 6287 | I20: 7423 | J20: 8650 | K20: 9936 | L20: 11898 | M20: 12353 | N20: 12925
B21: Furniture n fittings | C21: 805 | D21: 958 | E21: 1444 | F21: 1277 | G21: 1393 | H21: 1620 | I21: 2073 | J21: 2149 | K21: 2279 | L21: 2303 | M21: 2326 | N21: 2340
B22: Vehicles | C22: 35 | D22: 34 | E22: 29 | F22: 31 | G22: 31 | H22: 38 | I22: 69 | J22: 74 | K22: 71 | L22: 60 | M22: 62 | N22: 72
B23: Intangible Assets | C23: 2244 | D23: 3637 | E23: 3858 | F23: 3743 | G23: 2237 | H23: 3640 | I23: 5527 | J23: 6372 | K23: 6495 | L23: 7594 | M23: 7653 | N23: 10626
B24: Other fixed assets | C24: 126 | D24: 71 | E24: 931 | F24: 899 | G24: 545 | H24: 1093 | I24: 2289 | J24: 2730 | K24: 2766 | L24: 3281 | M24: 3294 | N24: 5184
B25: Gross Block | C25: 13950 | D25: 17816 | E25: 21293 | F25: 23379 | G25: 22980 | H25: 28065 | I25: 38885 | J25: 43006 | K25: 45010 | L25: 48877 | M25: 49196 | N25: 54691
B26: Accumulated Depreciation | C26: 5572 | D26: 6470 | E26: 7907 | F26: 9200 | G26: 10406 | H26: 12355 | I26: 15096 | J26: 17501 | K26: 19210 | L26: 19652 | M26: 21574 | N26: 23730
B27: Net Block | C27: =C25-C26 -> 8378 | D27: =D25-D26 -> 11346 | E27: =E25-E26 -> 13386 | F27: =F25-F26 -> 14179 | G27: =G25-G26 -> 12574 | H27: =H25-H26 -> 15710 | I27: =I25-I26 -> 23789 | J27: =J25-J26 -> 25505 | ... N27: =N25-N26 -> 30961
B29: CWIP | C29: 961 | D29: 776 | E29: 960 | F29: 1365 | G29: 1606 | H29: 1388 | I29: 954 | J29: 922 | K29: 416 | L29: 288 | M29: 293 | N29: 814
B30: Investments | C30: 4331 | D30: 2270 | E30: 1892 | F30: 16423 | G30: 12163 | H30: 11261 | I30: 8792 | J30: 14205 | K30: 20324 | L30: 19478 | M30: 24623 | N30: 23541
B32: Other Assets -
B33: Trade receivables | C33: 8351 | D33: 9713 | E33: 11330 | F33: 12322 | G33: 13142 | H33: 14827 | I33: 18487 | J33: 19294 | K33: 22698 | L33: 25424 | M33: 30193 | N33: 31158
B34: Cash Equivalents | C34: 25950 | D34: 30367 | E34: 32697 | F34: 22625 | G34: 19818 | H34: 19568 | I34: 18649 | J34: 24714 | K34: 17472 | L34: 12173 | M34: 14786 | N34: 24455
B35: Loans n Advances | C35: 1484 | D35: 399 | E35: 614 | F35: 844 | G35: 830 | H35: 1524 | I35: 1359 | J35: 1460 | K35: 2491 | L35: 3242 | M35: 10330 | N35: 6717
B36: Other asset items | C36: 7511 | D36: 11418 | E36: 14219 | F36: 15390 | G36: 19216 | H36: 19788 | I36: 19770 | J36: 21411 | K36: 27528 | L36: 34766 | M36: 29513 | N36: 30149
B37: Total Assets | C37: 56966 | D37: 66289 | E37: 75098 | F37: 83148 | G37: 79349 | H37: 84066 | I37: 91800 | J37: 107511 | K37: 116729 | L37: 124596 | M37: 137360 | N37: 147795
B40: Cash from Operating Activity - | C40: 9825 | D40: 8353 | E40: 10028 | F40: 11531 | G40: 13218 | H40: 14841 | I40: 17003 | J40: 23224 | K40: 23885 | L40: 22467 | M40: 25210 | N40: 35694
B41: Profit from operations | C41: 14172 | D41: 15946 | E41: 17839 | F41: 19340 | G41: 19963 | H41: 22126 | I41: 23920 | J41: 28845 | K41: 32921 | L41: 37605 | M41: 39523 | N41: 41591
B42: Receivables | C42: -1406 | D42: -1475 | E42: -1654 | F42: -1743 | G42: -1523 | H42: -2881 | I42: -3861 | J42: -1835 | K42: -7937 | L42: -7076 | M42: -2667 | N42: -1769
B43: Payables | C43: 0 | D43: 0 | E43: 242 | F43: -19 | G43: 328 | H43: 916 | I43: -373 | J43: -245 | K43: 1489 | L43: -279 | M43: 91 | N43: 176
B44: Loans Advances | C44: -1060 | D44: -221 | E44: -1134 | F44: 0 | G44: 0 | H44: 0 | I44: 0 | J44: -534 | K44: -1914 | L44: -3108 | M44: -1172 | N44: -1024
B45: Other WC items | C45: 1993 | D45: 854 | E45: 600 | F45: -394 | G45: 1279 | H45: 1512 | I45: 1867 | J45: 3382 | K45: 6938 | L45: 4119 | M45: -1334 | N45: 2322
B46: Working capital changes | C46: -473 | D46: -842 | E46: -1946 | F46: -2156 | G46: 84 | H46: -453 | I46: -2367 | J46: 768 | K46: -1424 | L46: -6344 | M46: -5082 | N46: -295
... B64: Net Cash Flow | C64: 4118 | D64: 4417 | E64: 2330 | F64: -10072 | G64: -2754 | H64: -303 | I64: -919 | J64: 6065 | K64: -7242 | L64: -5299 | M64: 2613 | N64: 9669
